2025-05-13 11:12:37,749 - CatastoAppLogger - INFO - Avvio Applicazione Catasto Storico...
2025-05-13 11:12:37,753 - CatastoAppLogger.ConfigLoader - INFO - Configurazione database caricata da 'config.ini'.
2025-05-13 11:12:37,754 - CatastoDBLogger - INFO - Tentativo di connessione al database: catasto_storico@localhost
2025-05-13 11:12:37,756 - CatastoDBLogger - ERROR - Errore di connessione al database: invalid dsn: invalid connection option "schema"
Traceback (most recent call last):
  File "C:\Users\saint\catasto\acs\core\db_manager.py", line 27, in connect
    self.conn = psycopg2.connect(**self.db_config)
                ~~~~~~~~~~~~~~~~^^^^^^^^^^^^^^^^^^
  File "C:\Users\saint\AppData\Local\Programs\Python\Python313\Lib\site-packages\psycopg2\__init__.py", line 134, in connect
    dsn = _ext.make_dsn(dsn, **kwargs)
  File "C:\Users\saint\AppData\Local\Programs\Python\Python313\Lib\site-packages\psycopg2\extensions.py", line 167, in make_dsn
    parse_dsn(dsn)
    ~~~~~~~~~^^^^^
psycopg2.ProgrammingError: invalid dsn: invalid connection option "schema"

2025-05-13 11:12:37,770 - CatastoAppLogger - CRITICAL - Fallimento connessione al database all'avvio. L'applicazione terminerà.
2025-05-13 11:14:48,817 - CatastoAppLogger - INFO - Avvio Applicazione Catasto Storico...
2025-05-13 11:14:48,818 - CatastoAppLogger.ConfigLoader - INFO - Configurazione database caricata da 'config.ini'.
2025-05-13 11:14:48,819 - CatastoDBLogger - INFO - Tentativo di connessione al database: catasto_storico@localhost
2025-05-13 11:14:48,819 - CatastoDBLogger - ERROR - Errore di connessione al database: invalid dsn: invalid connection option "schema"
Traceback (most recent call last):
  File "C:\Users\saint\catasto\acs\core\db_manager.py", line 27, in connect
    self.conn = psycopg2.connect(**self.db_config)
                ~~~~~~~~~~~~~~~~^^^^^^^^^^^^^^^^^^
  File "C:\Users\saint\AppData\Local\Programs\Python\Python313\Lib\site-packages\psycopg2\__init__.py", line 134, in connect
    dsn = _ext.make_dsn(dsn, **kwargs)
  File "C:\Users\saint\AppData\Local\Programs\Python\Python313\Lib\site-packages\psycopg2\extensions.py", line 167, in make_dsn
    parse_dsn(dsn)
    ~~~~~~~~~^^^^^
psycopg2.ProgrammingError: invalid dsn: invalid connection option "schema"

2025-05-13 11:14:48,833 - CatastoAppLogger - CRITICAL - Fallimento connessione al database all'avvio. L'applicazione terminerà.
2025-05-13 11:22:14,558 - CatastoAppLogger - INFO - Avvio Applicazione Catasto Storico...
2025-05-13 11:22:14,561 - CatastoAppLogger.ConfigLoader - INFO - Configurazione database caricata da 'config.ini'.
2025-05-13 11:22:14,561 - CatastoDBLogger - INFO - Tentativo di connessione al database: catasto_storico@localhost
2025-05-13 11:22:14,661 - CatastoDBLogger - INFO - Connessione al database 'catasto_storico' riuscita.
2025-05-13 11:22:14,673 - CatastoDBLogger - INFO - Search path impostato a: catasto, public
2025-05-13 11:22:14,674 - CatastoAppLogger - INFO - Indirizzo IP client rilevato/usato: 192.168.0.188
2025-05-13 11:22:40,239 - CatastoAppLogger.UtentiService - INFO - Tentativo di login per l'utente: Saintgold
2025-05-13 11:22:40,261 - CatastoDBLogger - ERROR - Errore Database durante l'esecuzione della query: SELECT id, password_hash, role_id, is_active FROM utenti WHERE username = %s... Errore: ERRORE:  la relazione "utenti" non esiste
LINE 1: SELECT id, password_hash, role_id, is_active FROM utenti WHE...
                                                          ^
Traceback (most recent call last):
  File "C:\Users\saint\catasto\acs\core\db_manager.py", line 180, in execute_query
    cur.execute(query, params)
    ~~~~~~~~~~~^^^^^^^^^^^^^^^
  File "C:\Users\saint\AppData\Local\Programs\Python\Python313\Lib\site-packages\psycopg2\extras.py", line 146, in execute
    return super().execute(query, vars)
           ~~~~~~~~~~~~~~~^^^^^^^^^^^^^
psycopg2.errors.UndefinedTable: ERRORE:  la relazione "utenti" non esiste
LINE 1: SELECT id, password_hash, role_id, is_active FROM utenti WHE...
                                                          ^

2025-05-13 11:22:40,277 - CatastoAppLogger - ERROR - Errore durante il tentativo di login: ERRORE:  la relazione "utenti" non esiste
LINE 1: SELECT id, password_hash, role_id, is_active FROM utenti WHE...
                                                          ^
Traceback (most recent call last):
  File "C:\Users\saint\catasto\acs\main_app.py", line 95, in authenticate_user
    user_id, role_id, session_id, message = utenti_service.login_user_service(
                                            ~~~~~~~~~~~~~~~~~~~~~~~~~~~~~~~~~^
        db_manager_instance, username, password, client_ip_address
        ^^^^^^^^^^^^^^^^^^^^^^^^^^^^^^^^^^^^^^^^^^^^^^^^^^^^^^^^^^
    )
    ^
  File "C:\Users\saint\catasto\acs\core\services\utenti_service.py", line 129, in login_user_service
    user_data = db_manager.execute_query(query, (username,), fetch_one=True)
  File "C:\Users\saint\catasto\acs\core\db_manager.py", line 180, in execute_query
    cur.execute(query, params)
    ~~~~~~~~~~~^^^^^^^^^^^^^^^
  File "C:\Users\saint\AppData\Local\Programs\Python\Python313\Lib\site-packages\psycopg2\extras.py", line 146, in execute
    return super().execute(query, vars)
           ~~~~~~~~~~~~~~~^^^^^^^^^^^^^
psycopg2.errors.UndefinedTable: ERRORE:  la relazione "utenti" non esiste
LINE 1: SELECT id, password_hash, role_id, is_active FROM utenti WHE...
                                                          ^

2025-05-13 11:24:05,551 - CatastoAppLogger.UtentiService - INFO - Tentativo di registrazione per l'utente: Saintgold
2025-05-13 11:24:05,566 - CatastoDBLogger - ERROR - Errore Database durante l'esecuzione della query: SELECT id FROM utenti WHERE username = %s OR email = %s... Errore: ERRORE:  la transazione corrente è interrotta, i comandi saranno ignorati fino alla fine del blocco della transazione
Traceback (most recent call last):
  File "C:\Users\saint\catasto\acs\core\db_manager.py", line 180, in execute_query
    cur.execute(query, params)
    ~~~~~~~~~~~^^^^^^^^^^^^^^^
  File "C:\Users\saint\AppData\Local\Programs\Python\Python313\Lib\site-packages\psycopg2\extras.py", line 146, in execute
    return super().execute(query, vars)
           ~~~~~~~~~~~~~~~^^^^^^^^^^^^^
psycopg2.errors.InFailedSqlTransaction: ERRORE:  la transazione corrente è interrotta, i comandi saranno ignorati fino alla fine del blocco della transazione

2025-05-13 11:24:05,569 - CatastoAppLogger - ERROR - Errore critico durante la registrazione: ERRORE:  la transazione corrente è interrotta, i comandi saranno ignorati fino alla fine del blocco della transazione
Traceback (most recent call last):
  File "C:\Users\saint\catasto\acs\main_app.py", line 137, in authenticate_user
    new_user_id = utenti_service.register_user_service(
        db_manager_instance, username_reg, password_reg1, email_reg,
        DEFAULT_SELF_REGISTER_ROLE_ID, client_ip_address=client_ip_address,
        created_by_user_id=None # Self-registration
    )
  File "C:\Users\saint\catasto\acs\core\services\utenti_service.py", line 51, in register_user_service
    existing_user = db_manager.execute_query(check_query, (username, email), fetch_one=True)
  File "C:\Users\saint\catasto\acs\core\db_manager.py", line 180, in execute_query
    cur.execute(query, params)
    ~~~~~~~~~~~^^^^^^^^^^^^^^^
  File "C:\Users\saint\AppData\Local\Programs\Python\Python313\Lib\site-packages\psycopg2\extras.py", line 146, in execute
    return super().execute(query, vars)
           ~~~~~~~~~~~~~~~^^^^^^^^^^^^^
psycopg2.errors.InFailedSqlTransaction: ERRORE:  la transazione corrente è interrotta, i comandi saranno ignorati fino alla fine del blocco della transazione

2025-05-13 11:25:22,451 - CatastoAppLogger - INFO - Autenticazione fallita o utente ha scelto di uscire. Chiusura applicazione.
2025-05-13 11:25:22,452 - CatastoDBLogger - INFO - Disconnessione dal database riuscita.
2025-05-13 11:42:57,829 - CatastoAppLogger - INFO - Avvio Applicazione Catasto Storico...
2025-05-13 11:42:57,832 - CatastoAppLogger.ConfigLoader - INFO - Configurazione database caricata da 'config.ini'.
2025-05-13 11:42:57,832 - CatastoDBLogger - INFO - Tentativo di connessione al database: catasto_storico@localhost
2025-05-13 11:42:57,939 - CatastoDBLogger - INFO - Connessione al database 'catasto_storico' riuscita.
2025-05-13 11:42:57,943 - CatastoDBLogger - INFO - Search path impostato a: catasto, public
2025-05-13 11:42:57,945 - CatastoAppLogger - INFO - Indirizzo IP client rilevato/usato: 192.168.0.188
2025-05-13 11:43:20,765 - CatastoAppLogger.UtentiService - INFO - Tentativo di registrazione per l'utente: Saintgold
2025-05-13 11:43:20,790 - CatastoDBLogger - ERROR - Errore Database durante l'esecuzione della query: SELECT id FROM utenti WHERE username = %s OR email = %s... Errore: ERRORE:  la relazione "utenti" non esiste
LINE 1: SELECT id FROM utenti WHERE username = 'Saintgold' OR email ...
                       ^
Traceback (most recent call last):
  File "C:\Users\saint\catasto\acs\core\db_manager.py", line 180, in execute_query
    cur.execute(query, params)
    ~~~~~~~~~~~^^^^^^^^^^^^^^^
  File "C:\Users\saint\AppData\Local\Programs\Python\Python313\Lib\site-packages\psycopg2\extras.py", line 146, in execute
    return super().execute(query, vars)
           ~~~~~~~~~~~~~~~^^^^^^^^^^^^^
psycopg2.errors.UndefinedTable: ERRORE:  la relazione "utenti" non esiste
LINE 1: SELECT id FROM utenti WHERE username = 'Saintgold' OR email ...
                       ^

2025-05-13 11:43:20,816 - CatastoAppLogger - ERROR - Errore critico durante la registrazione: ERRORE:  la relazione "utenti" non esiste
LINE 1: SELECT id FROM utenti WHERE username = 'Saintgold' OR email ...
                       ^
Traceback (most recent call last):
  File "C:\Users\saint\catasto\acs\main_app.py", line 137, in authenticate_user
    new_user_id = utenti_service.register_user_service(
        db_manager_instance, username_reg, password_reg1, email_reg,
        DEFAULT_SELF_REGISTER_ROLE_ID, client_ip_address=client_ip_address,
        created_by_user_id=None # Self-registration
    )
  File "C:\Users\saint\catasto\acs\core\services\utenti_service.py", line 51, in register_user_service
    existing_user = db_manager.execute_query(check_query, (username, email), fetch_one=True)
  File "C:\Users\saint\catasto\acs\core\db_manager.py", line 180, in execute_query
    cur.execute(query, params)
    ~~~~~~~~~~~^^^^^^^^^^^^^^^
  File "C:\Users\saint\AppData\Local\Programs\Python\Python313\Lib\site-packages\psycopg2\extras.py", line 146, in execute
    return super().execute(query, vars)
           ~~~~~~~~~~~~~~~^^^^^^^^^^^^^
psycopg2.errors.UndefinedTable: ERRORE:  la relazione "utenti" non esiste
LINE 1: SELECT id FROM utenti WHERE username = 'Saintgold' OR email ...
                       ^

2025-05-13 11:44:05,351 - CatastoAppLogger.UtentiService - INFO - Tentativo di login per l'utente: 0
2025-05-13 11:44:05,353 - CatastoDBLogger - ERROR - Errore Database durante l'esecuzione della query: SELECT id, password_hash, role_id, is_active FROM utenti WHERE username = %s... Errore: ERRORE:  la transazione corrente è interrotta, i comandi saranno ignorati fino alla fine del blocco della transazione
Traceback (most recent call last):
  File "C:\Users\saint\catasto\acs\core\db_manager.py", line 180, in execute_query
    cur.execute(query, params)
    ~~~~~~~~~~~^^^^^^^^^^^^^^^
  File "C:\Users\saint\AppData\Local\Programs\Python\Python313\Lib\site-packages\psycopg2\extras.py", line 146, in execute
    return super().execute(query, vars)
           ~~~~~~~~~~~~~~~^^^^^^^^^^^^^
psycopg2.errors.InFailedSqlTransaction: ERRORE:  la transazione corrente è interrotta, i comandi saranno ignorati fino alla fine del blocco della transazione

2025-05-13 11:44:05,359 - CatastoAppLogger - ERROR - Errore durante il tentativo di login: ERRORE:  la transazione corrente è interrotta, i comandi saranno ignorati fino alla fine del blocco della transazione
Traceback (most recent call last):
  File "C:\Users\saint\catasto\acs\main_app.py", line 95, in authenticate_user
    user_id, role_id, session_id, message = utenti_service.login_user_service(
                                            ~~~~~~~~~~~~~~~~~~~~~~~~~~~~~~~~~^
        db_manager_instance, username, password, client_ip_address
        ^^^^^^^^^^^^^^^^^^^^^^^^^^^^^^^^^^^^^^^^^^^^^^^^^^^^^^^^^^
    )
    ^
  File "C:\Users\saint\catasto\acs\core\services\utenti_service.py", line 129, in login_user_service
    user_data = db_manager.execute_query(query, (username,), fetch_one=True)
  File "C:\Users\saint\catasto\acs\core\db_manager.py", line 180, in execute_query
    cur.execute(query, params)
    ~~~~~~~~~~~^^^^^^^^^^^^^^^
  File "C:\Users\saint\AppData\Local\Programs\Python\Python313\Lib\site-packages\psycopg2\extras.py", line 146, in execute
    return super().execute(query, vars)
           ~~~~~~~~~~~~~~~^^^^^^^^^^^^^
psycopg2.errors.InFailedSqlTransaction: ERRORE:  la transazione corrente è interrotta, i comandi saranno ignorati fino alla fine del blocco della transazione

2025-05-13 11:44:09,193 - CatastoAppLogger - INFO - Autenticazione fallita o utente ha scelto di uscire. Chiusura applicazione.
2025-05-13 11:44:09,194 - CatastoDBLogger - INFO - Disconnessione dal database riuscita.
2025-05-13 11:52:21,988 - CatastoAppLogger - INFO - Avvio Applicazione Catasto Storico...
2025-05-13 11:52:21,991 - CatastoAppLogger.ConfigLoader - INFO - Configurazione database caricata da 'config.ini'.
2025-05-13 11:52:21,991 - CatastoDBLogger - INFO - Tentativo di connessione al database: catasto_storico@localhost
2025-05-13 11:52:22,085 - CatastoDBLogger - INFO - Connessione al database 'catasto_storico' riuscita.
2025-05-13 11:52:22,086 - CatastoDBLogger - INFO - Search path impostato a: catasto, public
2025-05-13 11:52:22,088 - CatastoAppLogger - INFO - Indirizzo IP client rilevato/usato: 192.168.0.188
2025-05-13 11:52:43,792 - CatastoAppLogger.UtentiService - INFO - Tentativo di registrazione per l'utente: Saintgold
2025-05-13 11:52:44,143 - CatastoDBLogger - ERROR - Errore Database durante l'esecuzione della query: 
        INSERT INTO utenti (username, password_hash, email, role_id, is_active, created_at, updated_at)
        VALUES (%s, %s, %s, %s, TRUE, NOW(), NOW()) RETURNING id
    ... Errore: ERRORE:  il valore nullo nella colonna "nome_completo" della relazione "utenti" viola il vincolo non nullo
DETAIL:  La riga in errore contiene (1, Saintgold, $2b$12$/q0f5CswhXNRIIOlPkdHIeugNXij28bXkkFKLMy/WSqaeXRGpKdUu, null, sa@gm.com, t, null, 2025-05-13 11:52:22.085472, 2025-05-13 11:52:22.085472, 2).
Traceback (most recent call last):
  File "C:\Users\saint\catasto\acs\core\db_manager.py", line 180, in execute_query
    cur.execute(query, params)
    ~~~~~~~~~~~^^^^^^^^^^^^^^^
  File "C:\Users\saint\AppData\Local\Programs\Python\Python313\Lib\site-packages\psycopg2\extras.py", line 146, in execute
    return super().execute(query, vars)
           ~~~~~~~~~~~~~~~^^^^^^^^^^^^^
psycopg2.errors.NotNullViolation: ERRORE:  il valore nullo nella colonna "nome_completo" della relazione "utenti" viola il vincolo non nullo
DETAIL:  La riga in errore contiene (1, Saintgold, $2b$12$/q0f5CswhXNRIIOlPkdHIeugNXij28bXkkFKLMy/WSqaeXRGpKdUu, null, sa@gm.com, t, null, 2025-05-13 11:52:22.085472, 2025-05-13 11:52:22.085472, 2).

2025-05-13 11:52:44,177 - CatastoDBLogger - INFO - Rollback della transazione eseguito.
2025-05-13 11:52:44,177 - CatastoAppLogger.UtentiService - ERROR - Errore critico durante la registrazione dell'utente 'Saintgold': ERRORE:  il valore nullo nella colonna "nome_completo" della relazione "utenti" viola il vincolo non nullo
DETAIL:  La riga in errore contiene (1, Saintgold, $2b$12$/q0f5CswhXNRIIOlPkdHIeugNXij28bXkkFKLMy/WSqaeXRGpKdUu, null, sa@gm.com, t, null, 2025-05-13 11:52:22.085472, 2025-05-13 11:52:22.085472, 2).
Traceback (most recent call last):
  File "C:\Users\saint\catasto\acs\core\services\utenti_service.py", line 100, in register_user_service
    user_record = db_manager.execute_query(insert_query, (username, hashed_pw_str_for_db, email, role_id), fetch_one=True)
  File "C:\Users\saint\catasto\acs\core\db_manager.py", line 180, in execute_query
    cur.execute(query, params)
    ~~~~~~~~~~~^^^^^^^^^^^^^^^
  File "C:\Users\saint\AppData\Local\Programs\Python\Python313\Lib\site-packages\psycopg2\extras.py", line 146, in execute
    return super().execute(query, vars)
           ~~~~~~~~~~~~~~~^^^^^^^^^^^^^
psycopg2.errors.NotNullViolation: ERRORE:  il valore nullo nella colonna "nome_completo" della relazione "utenti" viola il vincolo non nullo
DETAIL:  La riga in errore contiene (1, Saintgold, $2b$12$/q0f5CswhXNRIIOlPkdHIeugNXij28bXkkFKLMy/WSqaeXRGpKdUu, null, sa@gm.com, t, null, 2025-05-13 11:52:22.085472, 2025-05-13 11:52:22.085472, 2).

2025-05-13 11:52:44,188 - CatastoDBLogger - ERROR - Errore Database durante l'esecuzione della query: 
        INSERT INTO audit_log (user_id, session_id, client_ip_address, action_performed, 
                               table_name_affected, record_id_affected, details, success, timestamp)
        ... Errore: ERRORE:  la colonna "user_id" della relazione "audit_log" non esiste
LINE 2:         INSERT INTO audit_log (user_id, session_id, client_i...
                                       ^
Traceback (most recent call last):
  File "C:\Users\saint\catasto\acs\core\services\utenti_service.py", line 100, in register_user_service
    user_record = db_manager.execute_query(insert_query, (username, hashed_pw_str_for_db, email, role_id), fetch_one=True)
  File "C:\Users\saint\catasto\acs\core\db_manager.py", line 180, in execute_query
    cur.execute(query, params)
    ~~~~~~~~~~~^^^^^^^^^^^^^^^
  File "C:\Users\saint\AppData\Local\Programs\Python\Python313\Lib\site-packages\psycopg2\extras.py", line 146, in execute
    return super().execute(query, vars)
           ~~~~~~~~~~~~~~~^^^^^^^^^^^^^
psycopg2.errors.NotNullViolation: ERRORE:  il valore nullo nella colonna "nome_completo" della relazione "utenti" viola il vincolo non nullo
DETAIL:  La riga in errore contiene (1, Saintgold, $2b$12$/q0f5CswhXNRIIOlPkdHIeugNXij28bXkkFKLMy/WSqaeXRGpKdUu, null, sa@gm.com, t, null, 2025-05-13 11:52:22.085472, 2025-05-13 11:52:22.085472, 2).


During handling of the above exception, another exception occurred:

Traceback (most recent call last):
  File "C:\Users\saint\catasto\acs\core\db_manager.py", line 180, in execute_query
    cur.execute(query, params)
    ~~~~~~~~~~~^^^^^^^^^^^^^^^
  File "C:\Users\saint\AppData\Local\Programs\Python\Python313\Lib\site-packages\psycopg2\extras.py", line 146, in execute
    return super().execute(query, vars)
           ~~~~~~~~~~~~~~~^^^^^^^^^^^^^
psycopg2.errors.UndefinedColumn: ERRORE:  la colonna "user_id" della relazione "audit_log" non esiste
LINE 2:         INSERT INTO audit_log (user_id, session_id, client_i...
                                       ^

2025-05-13 11:52:44,193 - CatastoAppLogger.AuditService - ERROR - FALLIMENTO REGISTRAZIONE AUDIT: User None, Azione 'REGISTER_USER_FAIL'. Errore: ERRORE:  la colonna "user_id" della relazione "audit_log" non esiste
LINE 2:         INSERT INTO audit_log (user_id, session_id, client_i...
                                       ^
Traceback (most recent call last):
  File "C:\Users\saint\catasto\acs\core\services\utenti_service.py", line 100, in register_user_service
    user_record = db_manager.execute_query(insert_query, (username, hashed_pw_str_for_db, email, role_id), fetch_one=True)
  File "C:\Users\saint\catasto\acs\core\db_manager.py", line 180, in execute_query
    cur.execute(query, params)
    ~~~~~~~~~~~^^^^^^^^^^^^^^^
  File "C:\Users\saint\AppData\Local\Programs\Python\Python313\Lib\site-packages\psycopg2\extras.py", line 146, in execute
    return super().execute(query, vars)
           ~~~~~~~~~~~~~~~^^^^^^^^^^^^^
psycopg2.errors.NotNullViolation: ERRORE:  il valore nullo nella colonna "nome_completo" della relazione "utenti" viola il vincolo non nullo
DETAIL:  La riga in errore contiene (1, Saintgold, $2b$12$/q0f5CswhXNRIIOlPkdHIeugNXij28bXkkFKLMy/WSqaeXRGpKdUu, null, sa@gm.com, t, null, 2025-05-13 11:52:22.085472, 2025-05-13 11:52:22.085472, 2).


During handling of the above exception, another exception occurred:

Traceback (most recent call last):
  File "C:\Users\saint\catasto\acs\core\services\audit_service.py", line 26, in record_audit
    db_manager.execute_query(query, (
    ~~~~~~~~~~~~~~~~~~~~~~~~^^^^^^^^^
        user_id, session_id, client_ip_address, action,
        ^^^^^^^^^^^^^^^^^^^^^^^^^^^^^^^^^^^^^^^^^^^^^^^
        table_name, record_id_str, details, success, datetime.now()
        ^^^^^^^^^^^^^^^^^^^^^^^^^^^^^^^^^^^^^^^^^^^^^^^^^^^^^^^^^^^
    ))
    ^^
  File "C:\Users\saint\catasto\acs\core\db_manager.py", line 180, in execute_query
    cur.execute(query, params)
    ~~~~~~~~~~~^^^^^^^^^^^^^^^
  File "C:\Users\saint\AppData\Local\Programs\Python\Python313\Lib\site-packages\psycopg2\extras.py", line 146, in execute
    return super().execute(query, vars)
           ~~~~~~~~~~~~~~~^^^^^^^^^^^^^
psycopg2.errors.UndefinedColumn: ERRORE:  la colonna "user_id" della relazione "audit_log" non esiste
LINE 2:         INSERT INTO audit_log (user_id, session_id, client_i...
                                       ^

2025-05-13 11:52:44,202 - CatastoAppLogger - ERROR - Errore critico durante la registrazione: ERRORE:  il valore nullo nella colonna "nome_completo" della relazione "utenti" viola il vincolo non nullo
DETAIL:  La riga in errore contiene (1, Saintgold, $2b$12$/q0f5CswhXNRIIOlPkdHIeugNXij28bXkkFKLMy/WSqaeXRGpKdUu, null, sa@gm.com, t, null, 2025-05-13 11:52:22.085472, 2025-05-13 11:52:22.085472, 2).
Traceback (most recent call last):
  File "C:\Users\saint\catasto\acs\main_app.py", line 137, in authenticate_user
    new_user_id = utenti_service.register_user_service(
        db_manager_instance, username_reg, password_reg1, email_reg,
        DEFAULT_SELF_REGISTER_ROLE_ID, client_ip_address=client_ip_address,
        created_by_user_id=None # Self-registration
    )
  File "C:\Users\saint\catasto\acs\core\services\utenti_service.py", line 100, in register_user_service
    user_record = db_manager.execute_query(insert_query, (username, hashed_pw_str_for_db, email, role_id), fetch_one=True)
  File "C:\Users\saint\catasto\acs\core\db_manager.py", line 180, in execute_query
    cur.execute(query, params)
    ~~~~~~~~~~~^^^^^^^^^^^^^^^
  File "C:\Users\saint\AppData\Local\Programs\Python\Python313\Lib\site-packages\psycopg2\extras.py", line 146, in execute
    return super().execute(query, vars)
           ~~~~~~~~~~~~~~~^^^^^^^^^^^^^
psycopg2.errors.NotNullViolation: ERRORE:  il valore nullo nella colonna "nome_completo" della relazione "utenti" viola il vincolo non nullo
DETAIL:  La riga in errore contiene (1, Saintgold, $2b$12$/q0f5CswhXNRIIOlPkdHIeugNXij28bXkkFKLMy/WSqaeXRGpKdUu, null, sa@gm.com, t, null, 2025-05-13 11:52:22.085472, 2025-05-13 11:52:22.085472, 2).

2025-05-13 11:53:46,254 - CatastoAppLogger.UtentiService - INFO - Tentativo di registrazione per l'utente: Saintgold
2025-05-13 11:53:46,255 - CatastoDBLogger - ERROR - Errore Database durante l'esecuzione della query: SELECT id FROM utenti WHERE username = %s OR email = %s... Errore: ERRORE:  la transazione corrente è interrotta, i comandi saranno ignorati fino alla fine del blocco della transazione
Traceback (most recent call last):
  File "C:\Users\saint\catasto\acs\core\db_manager.py", line 180, in execute_query
    cur.execute(query, params)
    ~~~~~~~~~~~^^^^^^^^^^^^^^^
  File "C:\Users\saint\AppData\Local\Programs\Python\Python313\Lib\site-packages\psycopg2\extras.py", line 146, in execute
    return super().execute(query, vars)
           ~~~~~~~~~~~~~~~^^^^^^^^^^^^^
psycopg2.errors.InFailedSqlTransaction: ERRORE:  la transazione corrente è interrotta, i comandi saranno ignorati fino alla fine del blocco della transazione

2025-05-13 11:53:46,270 - CatastoAppLogger - ERROR - Errore critico durante la registrazione: ERRORE:  la transazione corrente è interrotta, i comandi saranno ignorati fino alla fine del blocco della transazione
Traceback (most recent call last):
  File "C:\Users\saint\catasto\acs\main_app.py", line 137, in authenticate_user
    new_user_id = utenti_service.register_user_service(
        db_manager_instance, username_reg, password_reg1, email_reg,
        DEFAULT_SELF_REGISTER_ROLE_ID, client_ip_address=client_ip_address,
        created_by_user_id=None # Self-registration
    )
  File "C:\Users\saint\catasto\acs\core\services\utenti_service.py", line 51, in register_user_service
    existing_user = db_manager.execute_query(check_query, (username, email), fetch_one=True)
  File "C:\Users\saint\catasto\acs\core\db_manager.py", line 180, in execute_query
    cur.execute(query, params)
    ~~~~~~~~~~~^^^^^^^^^^^^^^^
  File "C:\Users\saint\AppData\Local\Programs\Python\Python313\Lib\site-packages\psycopg2\extras.py", line 146, in execute
    return super().execute(query, vars)
           ~~~~~~~~~~~~~~~^^^^^^^^^^^^^
psycopg2.errors.InFailedSqlTransaction: ERRORE:  la transazione corrente è interrotta, i comandi saranno ignorati fino alla fine del blocco della transazione

2025-05-13 11:56:26,299 - CatastoAppLogger - INFO - Autenticazione fallita o utente ha scelto di uscire. Chiusura applicazione.
2025-05-13 11:56:26,300 - CatastoDBLogger - INFO - Disconnessione dal database riuscita.
2025-05-13 12:02:29,828 - CatastoAppLogger - INFO - Avvio Applicazione Catasto Storico...
2025-05-13 12:02:29,831 - CatastoAppLogger.ConfigLoader - INFO - Configurazione database caricata da 'config.ini'.
2025-05-13 12:02:29,831 - CatastoDBLogger - INFO - Tentativo di connessione al database: catasto_storico@localhost
2025-05-13 12:02:29,924 - CatastoDBLogger - INFO - Connessione al database 'catasto_storico' riuscita.
2025-05-13 12:02:29,926 - CatastoDBLogger - INFO - Search path impostato a: catasto, public
2025-05-13 12:02:29,928 - CatastoAppLogger - INFO - Indirizzo IP client rilevato/usato: 192.168.0.188
2025-05-13 12:02:47,182 - CatastoAppLogger.UtentiService - INFO - Tentativo di registrazione per l'utente: sa
2025-05-13 12:02:47,583 - CatastoDBLogger - ERROR - Errore Database durante l'esecuzione della query: 
        INSERT INTO utenti (username, password_hash, email, role_id, is_active, created_at, updated_at)
        VALUES (%s, %s, %s, %s, TRUE, NOW(), NOW()) RETURNING id
    ... Errore: ERRORE:  il valore nullo nella colonna "nome_completo" della relazione "utenti" viola il vincolo non nullo
DETAIL:  La riga in errore contiene (2, sa, $2b$12$hv1E66ERk3hTzFds2Z5gieMpJf4crP1Q7WOPkTv7.a5VqE.t5pgpG, null, sa@sa.com, t, null, 2025-05-13 12:02:47.555138, 2025-05-13 12:02:47.555138, 2).
Traceback (most recent call last):
  File "C:\Users\saint\catasto\acs\core\db_manager.py", line 181, in execute_query
    cur.execute(query, params)
    ~~~~~~~~~~~^^^^^^^^^^^^^^^
  File "C:\Users\saint\AppData\Local\Programs\Python\Python313\Lib\site-packages\psycopg2\extras.py", line 146, in execute
    return super().execute(query, vars)
           ~~~~~~~~~~~~~~~^^^^^^^^^^^^^
psycopg2.errors.NotNullViolation: ERRORE:  il valore nullo nella colonna "nome_completo" della relazione "utenti" viola il vincolo non nullo
DETAIL:  La riga in errore contiene (2, sa, $2b$12$hv1E66ERk3hTzFds2Z5gieMpJf4crP1Q7WOPkTv7.a5VqE.t5pgpG, null, sa@sa.com, t, null, 2025-05-13 12:02:47.555138, 2025-05-13 12:02:47.555138, 2).

2025-05-13 12:02:47,604 - CatastoDBLogger - INFO - Rollback della transazione eseguito.
2025-05-13 12:02:47,604 - CatastoAppLogger.UtentiService - ERROR - Errore critico durante la registrazione dell'utente 'sa': ERRORE:  il valore nullo nella colonna "nome_completo" della relazione "utenti" viola il vincolo non nullo
DETAIL:  La riga in errore contiene (2, sa, $2b$12$hv1E66ERk3hTzFds2Z5gieMpJf4crP1Q7WOPkTv7.a5VqE.t5pgpG, null, sa@sa.com, t, null, 2025-05-13 12:02:47.555138, 2025-05-13 12:02:47.555138, 2).
Traceback (most recent call last):
  File "C:\Users\saint\catasto\acs\core\services\utenti_service.py", line 100, in register_user_service
    user_record = db_manager.execute_query(insert_query, (username, hashed_pw_str_for_db, email, role_id), fetch_one=True)
  File "C:\Users\saint\catasto\acs\core\db_manager.py", line 181, in execute_query
    cur.execute(query, params)
    ~~~~~~~~~~~^^^^^^^^^^^^^^^
  File "C:\Users\saint\AppData\Local\Programs\Python\Python313\Lib\site-packages\psycopg2\extras.py", line 146, in execute
    return super().execute(query, vars)
           ~~~~~~~~~~~~~~~^^^^^^^^^^^^^
psycopg2.errors.NotNullViolation: ERRORE:  il valore nullo nella colonna "nome_completo" della relazione "utenti" viola il vincolo non nullo
DETAIL:  La riga in errore contiene (2, sa, $2b$12$hv1E66ERk3hTzFds2Z5gieMpJf4crP1Q7WOPkTv7.a5VqE.t5pgpG, null, sa@sa.com, t, null, 2025-05-13 12:02:47.555138, 2025-05-13 12:02:47.555138, 2).

2025-05-13 12:02:47,615 - CatastoDBLogger - ERROR - Errore Database durante l'esecuzione della query: 
        INSERT INTO audit_log (user_id, session_id, client_ip_address, action_performed, 
                               table_name_affected, record_id_affected, details, success, timestamp)
        ... Errore: ERRORE:  la colonna "user_id" della relazione "audit_log" non esiste
LINE 2:         INSERT INTO audit_log (user_id, session_id, client_i...
                                       ^
Traceback (most recent call last):
  File "C:\Users\saint\catasto\acs\core\services\utenti_service.py", line 100, in register_user_service
    user_record = db_manager.execute_query(insert_query, (username, hashed_pw_str_for_db, email, role_id), fetch_one=True)
  File "C:\Users\saint\catasto\acs\core\db_manager.py", line 181, in execute_query
    cur.execute(query, params)
    ~~~~~~~~~~~^^^^^^^^^^^^^^^
  File "C:\Users\saint\AppData\Local\Programs\Python\Python313\Lib\site-packages\psycopg2\extras.py", line 146, in execute
    return super().execute(query, vars)
           ~~~~~~~~~~~~~~~^^^^^^^^^^^^^
psycopg2.errors.NotNullViolation: ERRORE:  il valore nullo nella colonna "nome_completo" della relazione "utenti" viola il vincolo non nullo
DETAIL:  La riga in errore contiene (2, sa, $2b$12$hv1E66ERk3hTzFds2Z5gieMpJf4crP1Q7WOPkTv7.a5VqE.t5pgpG, null, sa@sa.com, t, null, 2025-05-13 12:02:47.555138, 2025-05-13 12:02:47.555138, 2).


During handling of the above exception, another exception occurred:

Traceback (most recent call last):
  File "C:\Users\saint\catasto\acs\core\db_manager.py", line 181, in execute_query
    cur.execute(query, params)
    ~~~~~~~~~~~^^^^^^^^^^^^^^^
  File "C:\Users\saint\AppData\Local\Programs\Python\Python313\Lib\site-packages\psycopg2\extras.py", line 146, in execute
    return super().execute(query, vars)
           ~~~~~~~~~~~~~~~^^^^^^^^^^^^^
psycopg2.errors.UndefinedColumn: ERRORE:  la colonna "user_id" della relazione "audit_log" non esiste
LINE 2:         INSERT INTO audit_log (user_id, session_id, client_i...
                                       ^

2025-05-13 12:02:47,620 - CatastoAppLogger.AuditService - ERROR - FALLIMENTO REGISTRAZIONE AUDIT: User None, Azione 'REGISTER_USER_FAIL'. Errore: ERRORE:  la colonna "user_id" della relazione "audit_log" non esiste
LINE 2:         INSERT INTO audit_log (user_id, session_id, client_i...
                                       ^
Traceback (most recent call last):
  File "C:\Users\saint\catasto\acs\core\services\utenti_service.py", line 100, in register_user_service
    user_record = db_manager.execute_query(insert_query, (username, hashed_pw_str_for_db, email, role_id), fetch_one=True)
  File "C:\Users\saint\catasto\acs\core\db_manager.py", line 181, in execute_query
    cur.execute(query, params)
    ~~~~~~~~~~~^^^^^^^^^^^^^^^
  File "C:\Users\saint\AppData\Local\Programs\Python\Python313\Lib\site-packages\psycopg2\extras.py", line 146, in execute
    return super().execute(query, vars)
           ~~~~~~~~~~~~~~~^^^^^^^^^^^^^
psycopg2.errors.NotNullViolation: ERRORE:  il valore nullo nella colonna "nome_completo" della relazione "utenti" viola il vincolo non nullo
DETAIL:  La riga in errore contiene (2, sa, $2b$12$hv1E66ERk3hTzFds2Z5gieMpJf4crP1Q7WOPkTv7.a5VqE.t5pgpG, null, sa@sa.com, t, null, 2025-05-13 12:02:47.555138, 2025-05-13 12:02:47.555138, 2).


During handling of the above exception, another exception occurred:

Traceback (most recent call last):
  File "C:\Users\saint\catasto\acs\core\services\audit_service.py", line 26, in record_audit
    db_manager.execute_query(query, (
    ~~~~~~~~~~~~~~~~~~~~~~~~^^^^^^^^^
        user_id, session_id, client_ip_address, action,
        ^^^^^^^^^^^^^^^^^^^^^^^^^^^^^^^^^^^^^^^^^^^^^^^
        table_name, record_id_str, details, success, datetime.now()
        ^^^^^^^^^^^^^^^^^^^^^^^^^^^^^^^^^^^^^^^^^^^^^^^^^^^^^^^^^^^
    ))
    ^^
  File "C:\Users\saint\catasto\acs\core\db_manager.py", line 181, in execute_query
    cur.execute(query, params)
    ~~~~~~~~~~~^^^^^^^^^^^^^^^
  File "C:\Users\saint\AppData\Local\Programs\Python\Python313\Lib\site-packages\psycopg2\extras.py", line 146, in execute
    return super().execute(query, vars)
           ~~~~~~~~~~~~~~~^^^^^^^^^^^^^
psycopg2.errors.UndefinedColumn: ERRORE:  la colonna "user_id" della relazione "audit_log" non esiste
LINE 2:         INSERT INTO audit_log (user_id, session_id, client_i...
                                       ^

2025-05-13 12:02:47,630 - CatastoAppLogger - ERROR - Errore critico durante la registrazione: ERRORE:  il valore nullo nella colonna "nome_completo" della relazione "utenti" viola il vincolo non nullo
DETAIL:  La riga in errore contiene (2, sa, $2b$12$hv1E66ERk3hTzFds2Z5gieMpJf4crP1Q7WOPkTv7.a5VqE.t5pgpG, null, sa@sa.com, t, null, 2025-05-13 12:02:47.555138, 2025-05-13 12:02:47.555138, 2).
Traceback (most recent call last):
  File "C:\Users\saint\catasto\acs\main_app.py", line 137, in authenticate_user
    new_user_id = utenti_service.register_user_service(
        db_manager_instance, username_reg, password_reg1, email_reg,
        DEFAULT_SELF_REGISTER_ROLE_ID, client_ip_address=client_ip_address,
        created_by_user_id=None # Self-registration
    )
  File "C:\Users\saint\catasto\acs\core\services\utenti_service.py", line 100, in register_user_service
    user_record = db_manager.execute_query(insert_query, (username, hashed_pw_str_for_db, email, role_id), fetch_one=True)
  File "C:\Users\saint\catasto\acs\core\db_manager.py", line 181, in execute_query
    cur.execute(query, params)
    ~~~~~~~~~~~^^^^^^^^^^^^^^^
  File "C:\Users\saint\AppData\Local\Programs\Python\Python313\Lib\site-packages\psycopg2\extras.py", line 146, in execute
    return super().execute(query, vars)
           ~~~~~~~~~~~~~~~^^^^^^^^^^^^^
psycopg2.errors.NotNullViolation: ERRORE:  il valore nullo nella colonna "nome_completo" della relazione "utenti" viola il vincolo non nullo
DETAIL:  La riga in errore contiene (2, sa, $2b$12$hv1E66ERk3hTzFds2Z5gieMpJf4crP1Q7WOPkTv7.a5VqE.t5pgpG, null, sa@sa.com, t, null, 2025-05-13 12:02:47.555138, 2025-05-13 12:02:47.555138, 2).

2025-05-13 12:56:58,074 - CatastoAppLogger - INFO - Avvio Applicazione Catasto Storico...
2025-05-13 12:56:58,079 - CatastoAppLogger.ConfigLoader - INFO - Configurazione database caricata da 'config.ini'.
2025-05-13 12:56:58,079 - CatastoDBLogger - INFO - Tentativo di connessione al database: catasto_storico@localhost
2025-05-13 12:56:58,201 - CatastoDBLogger - INFO - Connessione al database 'catasto_storico' riuscita.
2025-05-13 12:56:58,210 - CatastoDBLogger - INFO - Search path impostato a: catasto, public
2025-05-13 12:56:58,212 - CatastoAppLogger - INFO - Indirizzo IP client rilevato/usato: 192.168.0.188
2025-05-13 12:57:14,136 - CatastoAppLogger.UtentiService - INFO - Tentativo di registrazione per l'utente: sa
2025-05-13 12:57:15,224 - CatastoAppLogger.UtentiService - INFO - Utente 'sa' (ID: 3) registrato con successo.
2025-05-13 12:57:15,240 - CatastoDBLogger - ERROR - Errore Database durante l'esecuzione della query: 
        INSERT INTO audit_log (user_id, session_id, client_ip_address, action_performed, 
                               table_name_affected, record_id_affected, details, success, timestamp)
        ... Errore: ERRORE:  la colonna "user_id" della relazione "audit_log" non esiste
LINE 2:         INSERT INTO audit_log (user_id, session_id, client_i...
                                       ^
Traceback (most recent call last):
  File "C:\Users\saint\catasto\acs\core\db_manager.py", line 181, in execute_query
    cur.execute(query, params)
    ~~~~~~~~~~~^^^^^^^^^^^^^^^
  File "C:\Users\saint\AppData\Local\Programs\Python\Python313\Lib\site-packages\psycopg2\extras.py", line 146, in execute
    return super().execute(query, vars)
           ~~~~~~~~~~~~~~~^^^^^^^^^^^^^
psycopg2.errors.UndefinedColumn: ERRORE:  la colonna "user_id" della relazione "audit_log" non esiste
LINE 2:         INSERT INTO audit_log (user_id, session_id, client_i...
                                       ^

2025-05-13 12:57:15,287 - CatastoAppLogger.AuditService - ERROR - FALLIMENTO REGISTRAZIONE AUDIT: User 3, Azione 'REGISTER_USER_SUCCESS'. Errore: ERRORE:  la colonna "user_id" della relazione "audit_log" non esiste
LINE 2:         INSERT INTO audit_log (user_id, session_id, client_i...
                                       ^
Traceback (most recent call last):
  File "C:\Users\saint\catasto\acs\core\services\audit_service.py", line 26, in record_audit
    db_manager.execute_query(query, (
    ~~~~~~~~~~~~~~~~~~~~~~~~^^^^^^^^^
        user_id, session_id, client_ip_address, action,
        ^^^^^^^^^^^^^^^^^^^^^^^^^^^^^^^^^^^^^^^^^^^^^^^
        table_name, record_id_str, details, success, datetime.now()
        ^^^^^^^^^^^^^^^^^^^^^^^^^^^^^^^^^^^^^^^^^^^^^^^^^^^^^^^^^^^
    ))
    ^^
  File "C:\Users\saint\catasto\acs\core\db_manager.py", line 181, in execute_query
    cur.execute(query, params)
    ~~~~~~~~~~~^^^^^^^^^^^^^^^
  File "C:\Users\saint\AppData\Local\Programs\Python\Python313\Lib\site-packages\psycopg2\extras.py", line 146, in execute
    return super().execute(query, vars)
           ~~~~~~~~~~~~~~~^^^^^^^^^^^^^
psycopg2.errors.UndefinedColumn: ERRORE:  la colonna "user_id" della relazione "audit_log" non esiste
LINE 2:         INSERT INTO audit_log (user_id, session_id, client_i...
                                       ^

2025-05-13 12:57:32,603 - CatastoAppLogger.UtentiService - INFO - Tentativo di login per l'utente: sa
2025-05-13 12:57:33,584 - CatastoAppLogger.UtentiService - INFO - Utente 'sa' (ID: 3) loggato con successo. Sessione: 19dbd7e0-2d92-426a-a138-a200b12cbbab
2025-05-13 12:57:33,586 - CatastoDBLogger - ERROR - Errore Database durante l'esecuzione della query: 
        INSERT INTO audit_log (user_id, session_id, client_ip_address, action_performed, 
                               table_name_affected, record_id_affected, details, success, timestamp)
        ... Errore: ERRORE:  la colonna "user_id" della relazione "audit_log" non esiste
LINE 2:         INSERT INTO audit_log (user_id, session_id, client_i...
                                       ^
Traceback (most recent call last):
  File "C:\Users\saint\catasto\acs\core\db_manager.py", line 181, in execute_query
    cur.execute(query, params)
    ~~~~~~~~~~~^^^^^^^^^^^^^^^
  File "C:\Users\saint\AppData\Local\Programs\Python\Python313\Lib\site-packages\psycopg2\extras.py", line 146, in execute
    return super().execute(query, vars)
           ~~~~~~~~~~~~~~~^^^^^^^^^^^^^
psycopg2.errors.UndefinedColumn: ERRORE:  la colonna "user_id" della relazione "audit_log" non esiste
LINE 2:         INSERT INTO audit_log (user_id, session_id, client_i...
                                       ^

2025-05-13 12:57:33,590 - CatastoAppLogger.AuditService - ERROR - FALLIMENTO REGISTRAZIONE AUDIT: User 3, Azione 'LOGIN_SUCCESS'. Errore: ERRORE:  la colonna "user_id" della relazione "audit_log" non esiste
LINE 2:         INSERT INTO audit_log (user_id, session_id, client_i...
                                       ^
Traceback (most recent call last):
  File "C:\Users\saint\catasto\acs\core\services\audit_service.py", line 26, in record_audit
    db_manager.execute_query(query, (
    ~~~~~~~~~~~~~~~~~~~~~~~~^^^^^^^^^
        user_id, session_id, client_ip_address, action,
        ^^^^^^^^^^^^^^^^^^^^^^^^^^^^^^^^^^^^^^^^^^^^^^^
        table_name, record_id_str, details, success, datetime.now()
        ^^^^^^^^^^^^^^^^^^^^^^^^^^^^^^^^^^^^^^^^^^^^^^^^^^^^^^^^^^^
    ))
    ^^
  File "C:\Users\saint\catasto\acs\core\db_manager.py", line 181, in execute_query
    cur.execute(query, params)
    ~~~~~~~~~~~^^^^^^^^^^^^^^^
  File "C:\Users\saint\AppData\Local\Programs\Python\Python313\Lib\site-packages\psycopg2\extras.py", line 146, in execute
    return super().execute(query, vars)
           ~~~~~~~~~~~~~~~^^^^^^^^^^^^^
psycopg2.errors.UndefinedColumn: ERRORE:  la colonna "user_id" della relazione "audit_log" non esiste
LINE 2:         INSERT INTO audit_log (user_id, session_id, client_i...
                                       ^

2025-05-13 12:57:33,595 - CatastoAppLogger - INFO - Login successo per utente ID 3, Ruolo ID 2, Sessione 19dbd7e0-2d92-426a-a138-a200b12cbbab
2025-05-13 12:57:33,595 - CatastoAppLogger.MenuHandler - INFO - Utente ID 3 (Ruolo ID: 2, Sessione: 19dbd7e0-2d92-426a-a138-a200b12cbbab) ha effettuato l'accesso al menu principale.
2025-05-13 12:57:43,552 - CatastoDBLogger - ERROR - Errore Database durante l'esecuzione della query: SELECT id, nome, codice_catastale, provincia, regione, note FROM comuni ORDER BY nome... Errore: ERRORE:  la relazione "comuni" non esiste
LINE 1: ..., codice_catastale, provincia, regione, note FROM comuni ORD...
                                                             ^
Traceback (most recent call last):
  File "C:\Users\saint\catasto\acs\core\db_manager.py", line 181, in execute_query
    cur.execute(query, params)
    ~~~~~~~~~~~^^^^^^^^^^^^^^^
  File "C:\Users\saint\AppData\Local\Programs\Python\Python313\Lib\site-packages\psycopg2\extras.py", line 146, in execute
    return super().execute(query, vars)
           ~~~~~~~~~~~~~~~^^^^^^^^^^^^^
psycopg2.errors.UndefinedTable: ERRORE:  la relazione "comuni" non esiste
LINE 1: ..., codice_catastale, provincia, regione, note FROM comuni ORD...
                                                             ^

2025-05-13 12:57:43,558 - CatastoAppLogger.AnagraficheService - ERROR - Errore durante il recupero dei comuni: ERRORE:  la relazione "comuni" non esiste
LINE 1: ..., codice_catastale, provincia, regione, note FROM comuni ORD...
                                                             ^
Traceback (most recent call last):
  File "C:\Users\saint\catasto\acs\core\services\anagrafiche_service.py", line 67, in get_comuni_service
    comuni = db_manager.execute_query(query, params, fetch_all=True)
  File "C:\Users\saint\catasto\acs\core\db_manager.py", line 181, in execute_query
    cur.execute(query, params)
    ~~~~~~~~~~~^^^^^^^^^^^^^^^
  File "C:\Users\saint\AppData\Local\Programs\Python\Python313\Lib\site-packages\psycopg2\extras.py", line 146, in execute
    return super().execute(query, vars)
           ~~~~~~~~~~~~~~~^^^^^^^^^^^^^
psycopg2.errors.UndefinedTable: ERRORE:  la relazione "comuni" non esiste
LINE 1: ..., codice_catastale, provincia, regione, note FROM comuni ORD...
                                                             ^

2025-05-13 12:57:48,361 - CatastoAppLogger.MenuHandler - ERROR - Errore imprevisto durante l'operazione: search_partite_service() got an unexpected keyword argument 'current_user_id'
Traceback (most recent call last):
  File "C:\Users\saint\catasto\acs\ui\console\menu_handler.py", line 67, in _handle_service_call
    result = service_function(db_manager, *args, **audit_params if audit_params else {}, **kwargs)
TypeError: search_partite_service() got an unexpected keyword argument 'current_user_id'
2025-05-13 12:57:56,332 - CatastoDBLogger - ERROR - Errore Database durante l'esecuzione della query: SELECT id, nome, codice_catastale, provincia, regione, note FROM comuni ORDER BY nome... Errore: ERRORE:  la relazione "comuni" non esiste
LINE 1: ..., codice_catastale, provincia, regione, note FROM comuni ORD...
                                                             ^
Traceback (most recent call last):
  File "C:\Users\saint\catasto\acs\core\db_manager.py", line 181, in execute_query
    cur.execute(query, params)
    ~~~~~~~~~~~^^^^^^^^^^^^^^^
  File "C:\Users\saint\AppData\Local\Programs\Python\Python313\Lib\site-packages\psycopg2\extras.py", line 146, in execute
    return super().execute(query, vars)
           ~~~~~~~~~~~~~~~^^^^^^^^^^^^^
psycopg2.errors.UndefinedTable: ERRORE:  la relazione "comuni" non esiste
LINE 1: ..., codice_catastale, provincia, regione, note FROM comuni ORD...
                                                             ^

2025-05-13 12:57:56,337 - CatastoAppLogger.AnagraficheService - ERROR - Errore durante il recupero dei comuni: ERRORE:  la relazione "comuni" non esiste
LINE 1: ..., codice_catastale, provincia, regione, note FROM comuni ORD...
                                                             ^
Traceback (most recent call last):
  File "C:\Users\saint\catasto\acs\core\services\anagrafiche_service.py", line 67, in get_comuni_service
    comuni = db_manager.execute_query(query, params, fetch_all=True)
  File "C:\Users\saint\catasto\acs\core\db_manager.py", line 181, in execute_query
    cur.execute(query, params)
    ~~~~~~~~~~~^^^^^^^^^^^^^^^
  File "C:\Users\saint\AppData\Local\Programs\Python\Python313\Lib\site-packages\psycopg2\extras.py", line 146, in execute
    return super().execute(query, vars)
           ~~~~~~~~~~~~~~~^^^^^^^^^^^^^
psycopg2.errors.UndefinedTable: ERRORE:  la relazione "comuni" non esiste
LINE 1: ..., codice_catastale, provincia, regione, note FROM comuni ORD...
                                                             ^

2025-05-13 12:58:02,941 - CatastoAppLogger.MenuHandler - ERROR - Errore imprevisto durante l'operazione: search_partite_service() got an unexpected keyword argument 'current_user_id'
Traceback (most recent call last):
  File "C:\Users\saint\catasto\acs\ui\console\menu_handler.py", line 67, in _handle_service_call
    result = service_function(db_manager, *args, **audit_params if audit_params else {}, **kwargs)
TypeError: search_partite_service() got an unexpected keyword argument 'current_user_id'
2025-05-13 12:58:11,657 - CatastoDBLogger - ERROR - Errore Database durante l'esecuzione della query: SELECT id, nome, codice_catastale, provincia, regione, note FROM comuni ORDER BY nome... Errore: ERRORE:  la relazione "comuni" non esiste
LINE 1: ..., codice_catastale, provincia, regione, note FROM comuni ORD...
                                                             ^
Traceback (most recent call last):
  File "C:\Users\saint\catasto\acs\core\db_manager.py", line 181, in execute_query
    cur.execute(query, params)
    ~~~~~~~~~~~^^^^^^^^^^^^^^^
  File "C:\Users\saint\AppData\Local\Programs\Python\Python313\Lib\site-packages\psycopg2\extras.py", line 146, in execute
    return super().execute(query, vars)
           ~~~~~~~~~~~~~~~^^^^^^^^^^^^^
psycopg2.errors.UndefinedTable: ERRORE:  la relazione "comuni" non esiste
LINE 1: ..., codice_catastale, provincia, regione, note FROM comuni ORD...
                                                             ^

2025-05-13 12:58:11,664 - CatastoAppLogger.AnagraficheService - ERROR - Errore durante il recupero dei comuni: ERRORE:  la relazione "comuni" non esiste
LINE 1: ..., codice_catastale, provincia, regione, note FROM comuni ORD...
                                                             ^
Traceback (most recent call last):
  File "C:\Users\saint\catasto\acs\core\services\anagrafiche_service.py", line 67, in get_comuni_service
    comuni = db_manager.execute_query(query, params, fetch_all=True)
  File "C:\Users\saint\catasto\acs\core\db_manager.py", line 181, in execute_query
    cur.execute(query, params)
    ~~~~~~~~~~~^^^^^^^^^^^^^^^
  File "C:\Users\saint\AppData\Local\Programs\Python\Python313\Lib\site-packages\psycopg2\extras.py", line 146, in execute
    return super().execute(query, vars)
           ~~~~~~~~~~~~~~~^^^^^^^^^^^^^
psycopg2.errors.UndefinedTable: ERRORE:  la relazione "comuni" non esiste
LINE 1: ..., codice_catastale, provincia, regione, note FROM comuni ORD...
                                                             ^

2025-05-13 12:58:16,305 - CatastoAppLogger.MenuHandler - ERROR - Errore imprevisto durante l'operazione: search_partite_service() got an unexpected keyword argument 'current_user_id'
Traceback (most recent call last):
  File "C:\Users\saint\catasto\acs\ui\console\menu_handler.py", line 67, in _handle_service_call
    result = service_function(db_manager, *args, **audit_params if audit_params else {}, **kwargs)
TypeError: search_partite_service() got an unexpected keyword argument 'current_user_id'
2025-05-13 12:58:42,698 - CatastoDBLogger - ERROR - Errore Database durante l'esecuzione della query: SELECT id, nome, codice_catastale, provincia, regione, note FROM comuni ORDER BY nome... Errore: ERRORE:  la relazione "comuni" non esiste
LINE 1: ..., codice_catastale, provincia, regione, note FROM comuni ORD...
                                                             ^
Traceback (most recent call last):
  File "C:\Users\saint\catasto\acs\core\db_manager.py", line 181, in execute_query
    cur.execute(query, params)
    ~~~~~~~~~~~^^^^^^^^^^^^^^^
  File "C:\Users\saint\AppData\Local\Programs\Python\Python313\Lib\site-packages\psycopg2\extras.py", line 146, in execute
    return super().execute(query, vars)
           ~~~~~~~~~~~~~~~^^^^^^^^^^^^^
psycopg2.errors.UndefinedTable: ERRORE:  la relazione "comuni" non esiste
LINE 1: ..., codice_catastale, provincia, regione, note FROM comuni ORD...
                                                             ^

2025-05-13 12:58:42,704 - CatastoAppLogger.AnagraficheService - ERROR - Errore durante il recupero dei comuni: ERRORE:  la relazione "comuni" non esiste
LINE 1: ..., codice_catastale, provincia, regione, note FROM comuni ORD...
                                                             ^
Traceback (most recent call last):
  File "C:\Users\saint\catasto\acs\core\services\anagrafiche_service.py", line 67, in get_comuni_service
    comuni = db_manager.execute_query(query, params, fetch_all=True)
  File "C:\Users\saint\catasto\acs\core\db_manager.py", line 181, in execute_query
    cur.execute(query, params)
    ~~~~~~~~~~~^^^^^^^^^^^^^^^
  File "C:\Users\saint\AppData\Local\Programs\Python\Python313\Lib\site-packages\psycopg2\extras.py", line 146, in execute
    return super().execute(query, vars)
           ~~~~~~~~~~~~~~~^^^^^^^^^^^^^
psycopg2.errors.UndefinedTable: ERRORE:  la relazione "comuni" non esiste
LINE 1: ..., codice_catastale, provincia, regione, note FROM comuni ORD...
                                                             ^

2025-05-13 12:58:45,145 - CatastoAppLogger.MenuHandler - ERROR - Errore imprevisto durante l'operazione: search_partite_service() got an unexpected keyword argument 'current_user_id'
Traceback (most recent call last):
  File "C:\Users\saint\catasto\acs\ui\console\menu_handler.py", line 67, in _handle_service_call
    result = service_function(db_manager, *args, **audit_params if audit_params else {}, **kwargs)
TypeError: search_partite_service() got an unexpected keyword argument 'current_user_id'
2025-05-13 12:59:09,014 - CatastoAppLogger.MenuHandler - ERROR - Errore imprevisto durante l'operazione: get_comuni_service() got an unexpected keyword argument 'current_user_id'
Traceback (most recent call last):
  File "C:\Users\saint\catasto\acs\ui\console\menu_handler.py", line 67, in _handle_service_call
    result = service_function(db_manager, *args, **audit_params if audit_params else {}, **kwargs)
TypeError: get_comuni_service() got an unexpected keyword argument 'current_user_id'
2025-05-13 12:59:26,307 - CatastoDBLogger - ERROR - Errore Database durante l'esecuzione della query: SELECT id, nome, codice_catastale, provincia, regione, note FROM comuni ORDER BY nome... Errore: ERRORE:  la relazione "comuni" non esiste
LINE 1: ..., codice_catastale, provincia, regione, note FROM comuni ORD...
                                                             ^
Traceback (most recent call last):
  File "C:\Users\saint\catasto\acs\core\db_manager.py", line 181, in execute_query
    cur.execute(query, params)
    ~~~~~~~~~~~^^^^^^^^^^^^^^^
  File "C:\Users\saint\AppData\Local\Programs\Python\Python313\Lib\site-packages\psycopg2\extras.py", line 146, in execute
    return super().execute(query, vars)
           ~~~~~~~~~~~~~~~^^^^^^^^^^^^^
psycopg2.errors.UndefinedTable: ERRORE:  la relazione "comuni" non esiste
LINE 1: ..., codice_catastale, provincia, regione, note FROM comuni ORD...
                                                             ^

2025-05-13 12:59:26,313 - CatastoAppLogger.AnagraficheService - ERROR - Errore durante il recupero dei comuni: ERRORE:  la relazione "comuni" non esiste
LINE 1: ..., codice_catastale, provincia, regione, note FROM comuni ORD...
                                                             ^
Traceback (most recent call last):
  File "C:\Users\saint\catasto\acs\core\services\anagrafiche_service.py", line 67, in get_comuni_service
    comuni = db_manager.execute_query(query, params, fetch_all=True)
  File "C:\Users\saint\catasto\acs\core\db_manager.py", line 181, in execute_query
    cur.execute(query, params)
    ~~~~~~~~~~~^^^^^^^^^^^^^^^
  File "C:\Users\saint\AppData\Local\Programs\Python\Python313\Lib\site-packages\psycopg2\extras.py", line 146, in execute
    return super().execute(query, vars)
           ~~~~~~~~~~~~~~~^^^^^^^^^^^^^
psycopg2.errors.UndefinedTable: ERRORE:  la relazione "comuni" non esiste
LINE 1: ..., codice_catastale, provincia, regione, note FROM comuni ORD...
                                                             ^

2025-05-13 12:59:35,932 - CatastoDBLogger - ERROR - Errore Database durante l'esecuzione della query: SELECT id, nome, codice_catastale, provincia, regione, note FROM comuni ORDER BY nome... Errore: ERRORE:  la relazione "comuni" non esiste
LINE 1: ..., codice_catastale, provincia, regione, note FROM comuni ORD...
                                                             ^
Traceback (most recent call last):
  File "C:\Users\saint\catasto\acs\core\db_manager.py", line 181, in execute_query
    cur.execute(query, params)
    ~~~~~~~~~~~^^^^^^^^^^^^^^^
  File "C:\Users\saint\AppData\Local\Programs\Python\Python313\Lib\site-packages\psycopg2\extras.py", line 146, in execute
    return super().execute(query, vars)
           ~~~~~~~~~~~~~~~^^^^^^^^^^^^^
psycopg2.errors.UndefinedTable: ERRORE:  la relazione "comuni" non esiste
LINE 1: ..., codice_catastale, provincia, regione, note FROM comuni ORD...
                                                             ^

2025-05-13 12:59:35,937 - CatastoAppLogger.AnagraficheService - ERROR - Errore durante il recupero dei comuni: ERRORE:  la relazione "comuni" non esiste
LINE 1: ..., codice_catastale, provincia, regione, note FROM comuni ORD...
                                                             ^
Traceback (most recent call last):
  File "C:\Users\saint\catasto\acs\core\services\anagrafiche_service.py", line 67, in get_comuni_service
    comuni = db_manager.execute_query(query, params, fetch_all=True)
  File "C:\Users\saint\catasto\acs\core\db_manager.py", line 181, in execute_query
    cur.execute(query, params)
    ~~~~~~~~~~~^^^^^^^^^^^^^^^
  File "C:\Users\saint\AppData\Local\Programs\Python\Python313\Lib\site-packages\psycopg2\extras.py", line 146, in execute
    return super().execute(query, vars)
           ~~~~~~~~~~~~~~~^^^^^^^^^^^^^
psycopg2.errors.UndefinedTable: ERRORE:  la relazione "comuni" non esiste
LINE 1: ..., codice_catastale, provincia, regione, note FROM comuni ORD...
                                                             ^

2025-05-13 12:59:50,363 - CatastoAppLogger - INFO - Esecuzione logout per utente ID 3, sessione 19dbd7e0-2d92-426a-a138-a200b12cbbab...
2025-05-13 12:59:50,364 - CatastoAppLogger.UtentiService - INFO - Tentativo di logout per utente ID: 3, Sessione: 19dbd7e0-2d92-426a-a138-a200b12cbbab
2025-05-13 12:59:50,404 - CatastoAppLogger.UtentiService - INFO - Logout utente ID 3, Sessione 19dbd7e0-2d92-426a-a138-a200b12cbbab registrato con successo.
2025-05-13 12:59:50,406 - CatastoDBLogger - ERROR - Errore Database durante l'esecuzione della query: 
        INSERT INTO audit_log (user_id, session_id, client_ip_address, action_performed, 
                               table_name_affected, record_id_affected, details, success, timestamp)
        ... Errore: ERRORE:  la colonna "user_id" della relazione "audit_log" non esiste
LINE 2:         INSERT INTO audit_log (user_id, session_id, client_i...
                                       ^
Traceback (most recent call last):
  File "C:\Users\saint\catasto\acs\core\db_manager.py", line 181, in execute_query
    cur.execute(query, params)
    ~~~~~~~~~~~^^^^^^^^^^^^^^^
  File "C:\Users\saint\AppData\Local\Programs\Python\Python313\Lib\site-packages\psycopg2\extras.py", line 146, in execute
    return super().execute(query, vars)
           ~~~~~~~~~~~~~~~^^^^^^^^^^^^^
psycopg2.errors.UndefinedColumn: ERRORE:  la colonna "user_id" della relazione "audit_log" non esiste
LINE 2:         INSERT INTO audit_log (user_id, session_id, client_i...
                                       ^

2025-05-13 12:59:50,413 - CatastoAppLogger.AuditService - ERROR - FALLIMENTO REGISTRAZIONE AUDIT: User 3, Azione 'LOGOUT_SUCCESS'. Errore: ERRORE:  la colonna "user_id" della relazione "audit_log" non esiste
LINE 2:         INSERT INTO audit_log (user_id, session_id, client_i...
                                       ^
Traceback (most recent call last):
  File "C:\Users\saint\catasto\acs\core\services\audit_service.py", line 26, in record_audit
    db_manager.execute_query(query, (
    ~~~~~~~~~~~~~~~~~~~~~~~~^^^^^^^^^
        user_id, session_id, client_ip_address, action,
        ^^^^^^^^^^^^^^^^^^^^^^^^^^^^^^^^^^^^^^^^^^^^^^^
        table_name, record_id_str, details, success, datetime.now()
        ^^^^^^^^^^^^^^^^^^^^^^^^^^^^^^^^^^^^^^^^^^^^^^^^^^^^^^^^^^^
    ))
    ^^
  File "C:\Users\saint\catasto\acs\core\db_manager.py", line 181, in execute_query
    cur.execute(query, params)
    ~~~~~~~~~~~^^^^^^^^^^^^^^^
  File "C:\Users\saint\AppData\Local\Programs\Python\Python313\Lib\site-packages\psycopg2\extras.py", line 146, in execute
    return super().execute(query, vars)
           ~~~~~~~~~~~~~~~^^^^^^^^^^^^^
psycopg2.errors.UndefinedColumn: ERRORE:  la colonna "user_id" della relazione "audit_log" non esiste
LINE 2:         INSERT INTO audit_log (user_id, session_id, client_i...
                                       ^

2025-05-13 12:59:50,419 - CatastoAppLogger - INFO - Chiusura connessione al database...
2025-05-13 12:59:50,420 - CatastoDBLogger - INFO - Disconnessione dal database riuscita.
2025-05-13 12:59:50,421 - CatastoAppLogger - INFO - Applicazione Catasto Storico terminata.
2025-05-13 13:31:35,893 - CatastoAppLogger - INFO - Avvio Applicazione Catasto Storico...
2025-05-13 13:31:35,898 - CatastoAppLogger.ConfigLoader - INFO - Configurazione database caricata da 'config.ini'.
2025-05-13 13:31:35,899 - CatastoDBLogger - INFO - Tentativo di connessione al database: catasto_storico@localhost
2025-05-13 13:31:35,987 - CatastoDBLogger - INFO - Connessione al database 'catasto_storico' riuscita.
2025-05-13 13:31:35,997 - CatastoDBLogger - INFO - Search path impostato a: catasto, public
2025-05-13 13:31:35,998 - CatastoAppLogger - INFO - Indirizzo IP client rilevato/usato: 192.168.0.188
2025-05-13 13:31:50,061 - CatastoAppLogger.UtentiService - INFO - Tentativo di login per l'utente: sa
2025-05-13 13:31:51,022 - CatastoAppLogger.UtentiService - INFO - Utente 'sa' (ID: 3) loggato con successo. Sessione: 8a4b6eba-10b2-4f1c-ad0b-0cc42a59fa32
2025-05-13 13:31:51,037 - CatastoDBLogger - ERROR - Errore Database durante l'esecuzione della query: 
        INSERT INTO audit_log (user_id, session_id, client_ip_address, action_performed, 
                               table_name_affected, record_id_affected, details, success, timestamp)
        ... Errore: ERRORE:  la colonna "user_id" della relazione "audit_log" non esiste
LINE 2:         INSERT INTO audit_log (user_id, session_id, client_i...
                                       ^
Traceback (most recent call last):
  File "C:\Users\saint\catasto\acs\core\db_manager.py", line 181, in execute_query
    cur.execute(query, params)
    ~~~~~~~~~~~^^^^^^^^^^^^^^^
  File "C:\Users\saint\AppData\Local\Programs\Python\Python313\Lib\site-packages\psycopg2\extras.py", line 146, in execute
    return super().execute(query, vars)
           ~~~~~~~~~~~~~~~^^^^^^^^^^^^^
psycopg2.errors.UndefinedColumn: ERRORE:  la colonna "user_id" della relazione "audit_log" non esiste
LINE 2:         INSERT INTO audit_log (user_id, session_id, client_i...
                                       ^

2025-05-13 13:31:51,059 - CatastoAppLogger.AuditService - ERROR - FALLIMENTO REGISTRAZIONE AUDIT: User 3, Azione 'LOGIN_SUCCESS'. Errore: ERRORE:  la colonna "user_id" della relazione "audit_log" non esiste
LINE 2:         INSERT INTO audit_log (user_id, session_id, client_i...
                                       ^
Traceback (most recent call last):
  File "C:\Users\saint\catasto\acs\core\services\audit_service.py", line 26, in record_audit
    db_manager.execute_query(query, (
    ~~~~~~~~~~~~~~~~~~~~~~~~^^^^^^^^^
        user_id, session_id, client_ip_address, action,
        ^^^^^^^^^^^^^^^^^^^^^^^^^^^^^^^^^^^^^^^^^^^^^^^
        table_name, record_id_str, details, success, datetime.now()
        ^^^^^^^^^^^^^^^^^^^^^^^^^^^^^^^^^^^^^^^^^^^^^^^^^^^^^^^^^^^
    ))
    ^^
  File "C:\Users\saint\catasto\acs\core\db_manager.py", line 181, in execute_query
    cur.execute(query, params)
    ~~~~~~~~~~~^^^^^^^^^^^^^^^
  File "C:\Users\saint\AppData\Local\Programs\Python\Python313\Lib\site-packages\psycopg2\extras.py", line 146, in execute
    return super().execute(query, vars)
           ~~~~~~~~~~~~~~~^^^^^^^^^^^^^
psycopg2.errors.UndefinedColumn: ERRORE:  la colonna "user_id" della relazione "audit_log" non esiste
LINE 2:         INSERT INTO audit_log (user_id, session_id, client_i...
                                       ^

2025-05-13 13:31:51,065 - CatastoAppLogger - INFO - Login successo per utente ID 3, Ruolo ID 2, Sessione 8a4b6eba-10b2-4f1c-ad0b-0cc42a59fa32
2025-05-13 13:31:51,066 - CatastoAppLogger.MenuHandler - INFO - Utente ID 3 (Ruolo ID: 2, Sessione: 8a4b6eba-10b2-4f1c-ad0b-0cc42a59fa32) ha effettuato l'accesso al menu principale.
2025-05-13 13:31:51,067 - CatastoAppLogger - ERROR - Errore non gestito nel ciclo principale dell'applicazione: name 'ADMIN_ROLE_ID' is not defined
Traceback (most recent call last):
  File "C:\Users\saint\catasto\acs\main_app.py", line 209, in main
    menu_principale(db, logged_in_user_id, current_user_role_id, current_session_id, client_ip_address)
    ~~~~~~~~~~~~~~~^^^^^^^^^^^^^^^^^^^^^^^^^^^^^^^^^^^^^^^^^^^^^^^^^^^^^^^^^^^^^^^^^^^^^^^^^^^^^^^^^^^^
  File "C:\Users\saint\catasto\acs\ui\console\menu_handler.py", line 936, in menu_principale
    if current_user_role_id == ADMIN_ROLE_ID:
                               ^^^^^^^^^^^^^
NameError: name 'ADMIN_ROLE_ID' is not defined
2025-05-13 13:31:51,082 - CatastoAppLogger - INFO - Esecuzione logout per utente ID 3, sessione 8a4b6eba-10b2-4f1c-ad0b-0cc42a59fa32...
2025-05-13 13:31:51,082 - CatastoAppLogger.UtentiService - INFO - Tentativo di logout per utente ID: 3, Sessione: 8a4b6eba-10b2-4f1c-ad0b-0cc42a59fa32
2025-05-13 13:31:51,086 - CatastoAppLogger.UtentiService - INFO - Logout utente ID 3, Sessione 8a4b6eba-10b2-4f1c-ad0b-0cc42a59fa32 registrato con successo.
2025-05-13 13:31:51,088 - CatastoDBLogger - ERROR - Errore Database durante l'esecuzione della query: 
        INSERT INTO audit_log (user_id, session_id, client_ip_address, action_performed, 
                               table_name_affected, record_id_affected, details, success, timestamp)
        ... Errore: ERRORE:  la colonna "user_id" della relazione "audit_log" non esiste
LINE 2:         INSERT INTO audit_log (user_id, session_id, client_i...
                                       ^
Traceback (most recent call last):
  File "C:\Users\saint\catasto\acs\core\db_manager.py", line 181, in execute_query
    cur.execute(query, params)
    ~~~~~~~~~~~^^^^^^^^^^^^^^^
  File "C:\Users\saint\AppData\Local\Programs\Python\Python313\Lib\site-packages\psycopg2\extras.py", line 146, in execute
    return super().execute(query, vars)
           ~~~~~~~~~~~~~~~^^^^^^^^^^^^^
psycopg2.errors.UndefinedColumn: ERRORE:  la colonna "user_id" della relazione "audit_log" non esiste
LINE 2:         INSERT INTO audit_log (user_id, session_id, client_i...
                                       ^

2025-05-13 13:31:51,092 - CatastoAppLogger.AuditService - ERROR - FALLIMENTO REGISTRAZIONE AUDIT: User 3, Azione 'LOGOUT_SUCCESS'. Errore: ERRORE:  la colonna "user_id" della relazione "audit_log" non esiste
LINE 2:         INSERT INTO audit_log (user_id, session_id, client_i...
                                       ^
Traceback (most recent call last):
  File "C:\Users\saint\catasto\acs\core\services\audit_service.py", line 26, in record_audit
    db_manager.execute_query(query, (
    ~~~~~~~~~~~~~~~~~~~~~~~~^^^^^^^^^
        user_id, session_id, client_ip_address, action,
        ^^^^^^^^^^^^^^^^^^^^^^^^^^^^^^^^^^^^^^^^^^^^^^^
        table_name, record_id_str, details, success, datetime.now()
        ^^^^^^^^^^^^^^^^^^^^^^^^^^^^^^^^^^^^^^^^^^^^^^^^^^^^^^^^^^^
    ))
    ^^
  File "C:\Users\saint\catasto\acs\core\db_manager.py", line 181, in execute_query
    cur.execute(query, params)
    ~~~~~~~~~~~^^^^^^^^^^^^^^^
  File "C:\Users\saint\AppData\Local\Programs\Python\Python313\Lib\site-packages\psycopg2\extras.py", line 146, in execute
    return super().execute(query, vars)
           ~~~~~~~~~~~~~~~^^^^^^^^^^^^^
psycopg2.errors.UndefinedColumn: ERRORE:  la colonna "user_id" della relazione "audit_log" non esiste
LINE 2:         INSERT INTO audit_log (user_id, session_id, client_i...
                                       ^

2025-05-13 13:31:51,097 - CatastoAppLogger - INFO - Chiusura connessione al database...
2025-05-13 13:31:51,097 - CatastoDBLogger - INFO - Disconnessione dal database riuscita.
2025-05-13 13:31:51,097 - CatastoAppLogger - INFO - Applicazione Catasto Storico terminata.
2025-05-13 13:31:58,397 - CatastoAppLogger - INFO - Avvio Applicazione Catasto Storico...
2025-05-13 13:31:58,399 - CatastoAppLogger.ConfigLoader - INFO - Configurazione database caricata da 'config.ini'.
2025-05-13 13:31:58,399 - CatastoDBLogger - INFO - Tentativo di connessione al database: catasto_storico@localhost
2025-05-13 13:31:58,613 - CatastoDBLogger - INFO - Connessione al database 'catasto_storico' riuscita.
2025-05-13 13:31:58,614 - CatastoDBLogger - INFO - Search path impostato a: catasto, public
2025-05-13 13:31:58,616 - CatastoAppLogger - INFO - Indirizzo IP client rilevato/usato: 192.168.0.188
2025-05-13 13:32:07,273 - CatastoAppLogger.UtentiService - INFO - Tentativo di login per l'utente: sa
2025-05-13 13:32:08,243 - CatastoAppLogger.UtentiService - INFO - Utente 'sa' (ID: 3) loggato con successo. Sessione: f77b6713-1e66-42d8-8f7b-3da9bebc9adc
2025-05-13 13:32:08,248 - CatastoDBLogger - ERROR - Errore Database durante l'esecuzione della query: 
        INSERT INTO audit_log (user_id, session_id, client_ip_address, action_performed, 
                               table_name_affected, record_id_affected, details, success, timestamp)
        ... Errore: ERRORE:  la colonna "user_id" della relazione "audit_log" non esiste
LINE 2:         INSERT INTO audit_log (user_id, session_id, client_i...
                                       ^
Traceback (most recent call last):
  File "C:\Users\saint\catasto\acs\core\db_manager.py", line 181, in execute_query
    cur.execute(query, params)
    ~~~~~~~~~~~^^^^^^^^^^^^^^^
  File "C:\Users\saint\AppData\Local\Programs\Python\Python313\Lib\site-packages\psycopg2\extras.py", line 146, in execute
    return super().execute(query, vars)
           ~~~~~~~~~~~~~~~^^^^^^^^^^^^^
psycopg2.errors.UndefinedColumn: ERRORE:  la colonna "user_id" della relazione "audit_log" non esiste
LINE 2:         INSERT INTO audit_log (user_id, session_id, client_i...
                                       ^

2025-05-13 13:32:08,275 - CatastoAppLogger.AuditService - ERROR - FALLIMENTO REGISTRAZIONE AUDIT: User 3, Azione 'LOGIN_SUCCESS'. Errore: ERRORE:  la colonna "user_id" della relazione "audit_log" non esiste
LINE 2:         INSERT INTO audit_log (user_id, session_id, client_i...
                                       ^
Traceback (most recent call last):
  File "C:\Users\saint\catasto\acs\core\services\audit_service.py", line 26, in record_audit
    db_manager.execute_query(query, (
    ~~~~~~~~~~~~~~~~~~~~~~~~^^^^^^^^^
        user_id, session_id, client_ip_address, action,
        ^^^^^^^^^^^^^^^^^^^^^^^^^^^^^^^^^^^^^^^^^^^^^^^
        table_name, record_id_str, details, success, datetime.now()
        ^^^^^^^^^^^^^^^^^^^^^^^^^^^^^^^^^^^^^^^^^^^^^^^^^^^^^^^^^^^
    ))
    ^^
  File "C:\Users\saint\catasto\acs\core\db_manager.py", line 181, in execute_query
    cur.execute(query, params)
    ~~~~~~~~~~~^^^^^^^^^^^^^^^
  File "C:\Users\saint\AppData\Local\Programs\Python\Python313\Lib\site-packages\psycopg2\extras.py", line 146, in execute
    return super().execute(query, vars)
           ~~~~~~~~~~~~~~~^^^^^^^^^^^^^
psycopg2.errors.UndefinedColumn: ERRORE:  la colonna "user_id" della relazione "audit_log" non esiste
LINE 2:         INSERT INTO audit_log (user_id, session_id, client_i...
                                       ^

2025-05-13 13:32:08,284 - CatastoAppLogger - INFO - Login successo per utente ID 3, Ruolo ID 2, Sessione f77b6713-1e66-42d8-8f7b-3da9bebc9adc
2025-05-13 13:32:08,284 - CatastoAppLogger.MenuHandler - INFO - Utente ID 3 (Ruolo ID: 2, Sessione: f77b6713-1e66-42d8-8f7b-3da9bebc9adc) ha effettuato l'accesso al menu principale.
2025-05-13 13:32:08,286 - CatastoAppLogger - ERROR - Errore non gestito nel ciclo principale dell'applicazione: name 'ADMIN_ROLE_ID' is not defined
Traceback (most recent call last):
  File "C:\Users\saint\catasto\acs\main_app.py", line 209, in main
    menu_principale(db, logged_in_user_id, current_user_role_id, current_session_id, client_ip_address)
    ~~~~~~~~~~~~~~~^^^^^^^^^^^^^^^^^^^^^^^^^^^^^^^^^^^^^^^^^^^^^^^^^^^^^^^^^^^^^^^^^^^^^^^^^^^^^^^^^^^^
  File "C:\Users\saint\catasto\acs\ui\console\menu_handler.py", line 936, in menu_principale
    if current_user_role_id == ADMIN_ROLE_ID:
                               ^^^^^^^^^^^^^
NameError: name 'ADMIN_ROLE_ID' is not defined
2025-05-13 13:32:08,309 - CatastoAppLogger - INFO - Esecuzione logout per utente ID 3, sessione f77b6713-1e66-42d8-8f7b-3da9bebc9adc...
2025-05-13 13:32:08,310 - CatastoAppLogger.UtentiService - INFO - Tentativo di logout per utente ID: 3, Sessione: f77b6713-1e66-42d8-8f7b-3da9bebc9adc
2025-05-13 13:32:08,312 - CatastoAppLogger.UtentiService - INFO - Logout utente ID 3, Sessione f77b6713-1e66-42d8-8f7b-3da9bebc9adc registrato con successo.
2025-05-13 13:32:08,313 - CatastoDBLogger - ERROR - Errore Database durante l'esecuzione della query: 
        INSERT INTO audit_log (user_id, session_id, client_ip_address, action_performed, 
                               table_name_affected, record_id_affected, details, success, timestamp)
        ... Errore: ERRORE:  la colonna "user_id" della relazione "audit_log" non esiste
LINE 2:         INSERT INTO audit_log (user_id, session_id, client_i...
                                       ^
Traceback (most recent call last):
  File "C:\Users\saint\catasto\acs\core\db_manager.py", line 181, in execute_query
    cur.execute(query, params)
    ~~~~~~~~~~~^^^^^^^^^^^^^^^
  File "C:\Users\saint\AppData\Local\Programs\Python\Python313\Lib\site-packages\psycopg2\extras.py", line 146, in execute
    return super().execute(query, vars)
           ~~~~~~~~~~~~~~~^^^^^^^^^^^^^
psycopg2.errors.UndefinedColumn: ERRORE:  la colonna "user_id" della relazione "audit_log" non esiste
LINE 2:         INSERT INTO audit_log (user_id, session_id, client_i...
                                       ^

2025-05-13 13:32:08,317 - CatastoAppLogger.AuditService - ERROR - FALLIMENTO REGISTRAZIONE AUDIT: User 3, Azione 'LOGOUT_SUCCESS'. Errore: ERRORE:  la colonna "user_id" della relazione "audit_log" non esiste
LINE 2:         INSERT INTO audit_log (user_id, session_id, client_i...
                                       ^
Traceback (most recent call last):
  File "C:\Users\saint\catasto\acs\core\services\audit_service.py", line 26, in record_audit
    db_manager.execute_query(query, (
    ~~~~~~~~~~~~~~~~~~~~~~~~^^^^^^^^^
        user_id, session_id, client_ip_address, action,
        ^^^^^^^^^^^^^^^^^^^^^^^^^^^^^^^^^^^^^^^^^^^^^^^
        table_name, record_id_str, details, success, datetime.now()
        ^^^^^^^^^^^^^^^^^^^^^^^^^^^^^^^^^^^^^^^^^^^^^^^^^^^^^^^^^^^
    ))
    ^^
  File "C:\Users\saint\catasto\acs\core\db_manager.py", line 181, in execute_query
    cur.execute(query, params)
    ~~~~~~~~~~~^^^^^^^^^^^^^^^
  File "C:\Users\saint\AppData\Local\Programs\Python\Python313\Lib\site-packages\psycopg2\extras.py", line 146, in execute
    return super().execute(query, vars)
           ~~~~~~~~~~~~~~~^^^^^^^^^^^^^
psycopg2.errors.UndefinedColumn: ERRORE:  la colonna "user_id" della relazione "audit_log" non esiste
LINE 2:         INSERT INTO audit_log (user_id, session_id, client_i...
                                       ^

2025-05-13 13:32:08,323 - CatastoAppLogger - INFO - Chiusura connessione al database...
2025-05-13 13:32:08,324 - CatastoDBLogger - INFO - Disconnessione dal database riuscita.
2025-05-13 13:32:08,324 - CatastoAppLogger - INFO - Applicazione Catasto Storico terminata.
2025-05-13 13:32:22,546 - CatastoAppLogger - INFO - Avvio Applicazione Catasto Storico...
2025-05-13 13:32:22,547 - CatastoAppLogger.ConfigLoader - INFO - Configurazione database caricata da 'config.ini'.
2025-05-13 13:32:22,548 - CatastoDBLogger - INFO - Tentativo di connessione al database: catasto_storico@localhost
2025-05-13 13:32:22,620 - CatastoDBLogger - INFO - Connessione al database 'catasto_storico' riuscita.
2025-05-13 13:32:22,621 - CatastoDBLogger - INFO - Search path impostato a: catasto, public
2025-05-13 13:32:22,623 - CatastoAppLogger - INFO - Indirizzo IP client rilevato/usato: 192.168.0.188
2025-05-13 13:32:49,305 - CatastoAppLogger.UtentiService - INFO - Tentativo di registrazione per l'utente: pippo
2025-05-13 13:32:50,314 - CatastoAppLogger.UtentiService - INFO - Utente 'pippo' (ID: 4) registrato con successo.
2025-05-13 13:32:50,319 - CatastoDBLogger - ERROR - Errore Database durante l'esecuzione della query: 
        INSERT INTO audit_log (user_id, session_id, client_ip_address, action_performed, 
                               table_name_affected, record_id_affected, details, success, timestamp)
        ... Errore: ERRORE:  la colonna "user_id" della relazione "audit_log" non esiste
LINE 2:         INSERT INTO audit_log (user_id, session_id, client_i...
                                       ^
Traceback (most recent call last):
  File "C:\Users\saint\catasto\acs\core\db_manager.py", line 181, in execute_query
    cur.execute(query, params)
    ~~~~~~~~~~~^^^^^^^^^^^^^^^
  File "C:\Users\saint\AppData\Local\Programs\Python\Python313\Lib\site-packages\psycopg2\extras.py", line 146, in execute
    return super().execute(query, vars)
           ~~~~~~~~~~~~~~~^^^^^^^^^^^^^
psycopg2.errors.UndefinedColumn: ERRORE:  la colonna "user_id" della relazione "audit_log" non esiste
LINE 2:         INSERT INTO audit_log (user_id, session_id, client_i...
                                       ^

2025-05-13 13:32:50,345 - CatastoAppLogger.AuditService - ERROR - FALLIMENTO REGISTRAZIONE AUDIT: User 4, Azione 'REGISTER_USER_SUCCESS'. Errore: ERRORE:  la colonna "user_id" della relazione "audit_log" non esiste
LINE 2:         INSERT INTO audit_log (user_id, session_id, client_i...
                                       ^
Traceback (most recent call last):
  File "C:\Users\saint\catasto\acs\core\services\audit_service.py", line 26, in record_audit
    db_manager.execute_query(query, (
    ~~~~~~~~~~~~~~~~~~~~~~~~^^^^^^^^^
        user_id, session_id, client_ip_address, action,
        ^^^^^^^^^^^^^^^^^^^^^^^^^^^^^^^^^^^^^^^^^^^^^^^
        table_name, record_id_str, details, success, datetime.now()
        ^^^^^^^^^^^^^^^^^^^^^^^^^^^^^^^^^^^^^^^^^^^^^^^^^^^^^^^^^^^
    ))
    ^^
  File "C:\Users\saint\catasto\acs\core\db_manager.py", line 181, in execute_query
    cur.execute(query, params)
    ~~~~~~~~~~~^^^^^^^^^^^^^^^
  File "C:\Users\saint\AppData\Local\Programs\Python\Python313\Lib\site-packages\psycopg2\extras.py", line 146, in execute
    return super().execute(query, vars)
           ~~~~~~~~~~~~~~~^^^^^^^^^^^^^
psycopg2.errors.UndefinedColumn: ERRORE:  la colonna "user_id" della relazione "audit_log" non esiste
LINE 2:         INSERT INTO audit_log (user_id, session_id, client_i...
                                       ^

2025-05-13 13:33:01,326 - CatastoAppLogger.UtentiService - INFO - Tentativo di login per l'utente: pippo
2025-05-13 13:33:02,243 - CatastoAppLogger.UtentiService - INFO - Utente 'pippo' (ID: 4) loggato con successo. Sessione: 98986337-2c57-46d5-bc7d-18554080e248
2025-05-13 13:33:02,245 - CatastoDBLogger - ERROR - Errore Database durante l'esecuzione della query: 
        INSERT INTO audit_log (user_id, session_id, client_ip_address, action_performed, 
                               table_name_affected, record_id_affected, details, success, timestamp)
        ... Errore: ERRORE:  la colonna "user_id" della relazione "audit_log" non esiste
LINE 2:         INSERT INTO audit_log (user_id, session_id, client_i...
                                       ^
Traceback (most recent call last):
  File "C:\Users\saint\catasto\acs\core\db_manager.py", line 181, in execute_query
    cur.execute(query, params)
    ~~~~~~~~~~~^^^^^^^^^^^^^^^
  File "C:\Users\saint\AppData\Local\Programs\Python\Python313\Lib\site-packages\psycopg2\extras.py", line 146, in execute
    return super().execute(query, vars)
           ~~~~~~~~~~~~~~~^^^^^^^^^^^^^
psycopg2.errors.UndefinedColumn: ERRORE:  la colonna "user_id" della relazione "audit_log" non esiste
LINE 2:         INSERT INTO audit_log (user_id, session_id, client_i...
                                       ^

2025-05-13 13:33:02,250 - CatastoAppLogger.AuditService - ERROR - FALLIMENTO REGISTRAZIONE AUDIT: User 4, Azione 'LOGIN_SUCCESS'. Errore: ERRORE:  la colonna "user_id" della relazione "audit_log" non esiste
LINE 2:         INSERT INTO audit_log (user_id, session_id, client_i...
                                       ^
Traceback (most recent call last):
  File "C:\Users\saint\catasto\acs\core\services\audit_service.py", line 26, in record_audit
    db_manager.execute_query(query, (
    ~~~~~~~~~~~~~~~~~~~~~~~~^^^^^^^^^
        user_id, session_id, client_ip_address, action,
        ^^^^^^^^^^^^^^^^^^^^^^^^^^^^^^^^^^^^^^^^^^^^^^^
        table_name, record_id_str, details, success, datetime.now()
        ^^^^^^^^^^^^^^^^^^^^^^^^^^^^^^^^^^^^^^^^^^^^^^^^^^^^^^^^^^^
    ))
    ^^
  File "C:\Users\saint\catasto\acs\core\db_manager.py", line 181, in execute_query
    cur.execute(query, params)
    ~~~~~~~~~~~^^^^^^^^^^^^^^^
  File "C:\Users\saint\AppData\Local\Programs\Python\Python313\Lib\site-packages\psycopg2\extras.py", line 146, in execute
    return super().execute(query, vars)
           ~~~~~~~~~~~~~~~^^^^^^^^^^^^^
psycopg2.errors.UndefinedColumn: ERRORE:  la colonna "user_id" della relazione "audit_log" non esiste
LINE 2:         INSERT INTO audit_log (user_id, session_id, client_i...
                                       ^

2025-05-13 13:33:02,256 - CatastoAppLogger - INFO - Login successo per utente ID 4, Ruolo ID 2, Sessione 98986337-2c57-46d5-bc7d-18554080e248
2025-05-13 13:33:02,256 - CatastoAppLogger.MenuHandler - INFO - Utente ID 4 (Ruolo ID: 2, Sessione: 98986337-2c57-46d5-bc7d-18554080e248) ha effettuato l'accesso al menu principale.
2025-05-13 13:33:02,257 - CatastoAppLogger - ERROR - Errore non gestito nel ciclo principale dell'applicazione: name 'ADMIN_ROLE_ID' is not defined
Traceback (most recent call last):
  File "C:\Users\saint\catasto\acs\main_app.py", line 209, in main
    menu_principale(db, logged_in_user_id, current_user_role_id, current_session_id, client_ip_address)
    ~~~~~~~~~~~~~~~^^^^^^^^^^^^^^^^^^^^^^^^^^^^^^^^^^^^^^^^^^^^^^^^^^^^^^^^^^^^^^^^^^^^^^^^^^^^^^^^^^^^
  File "C:\Users\saint\catasto\acs\ui\console\menu_handler.py", line 936, in menu_principale
    if current_user_role_id == ADMIN_ROLE_ID:
                               ^^^^^^^^^^^^^
NameError: name 'ADMIN_ROLE_ID' is not defined
2025-05-13 13:33:02,275 - CatastoAppLogger - INFO - Esecuzione logout per utente ID 4, sessione 98986337-2c57-46d5-bc7d-18554080e248...
2025-05-13 13:33:02,275 - CatastoAppLogger.UtentiService - INFO - Tentativo di logout per utente ID: 4, Sessione: 98986337-2c57-46d5-bc7d-18554080e248
2025-05-13 13:33:02,277 - CatastoAppLogger.UtentiService - INFO - Logout utente ID 4, Sessione 98986337-2c57-46d5-bc7d-18554080e248 registrato con successo.
2025-05-13 13:33:02,278 - CatastoDBLogger - ERROR - Errore Database durante l'esecuzione della query: 
        INSERT INTO audit_log (user_id, session_id, client_ip_address, action_performed, 
                               table_name_affected, record_id_affected, details, success, timestamp)
        ... Errore: ERRORE:  la colonna "user_id" della relazione "audit_log" non esiste
LINE 2:         INSERT INTO audit_log (user_id, session_id, client_i...
                                       ^
Traceback (most recent call last):
  File "C:\Users\saint\catasto\acs\core\db_manager.py", line 181, in execute_query
    cur.execute(query, params)
    ~~~~~~~~~~~^^^^^^^^^^^^^^^
  File "C:\Users\saint\AppData\Local\Programs\Python\Python313\Lib\site-packages\psycopg2\extras.py", line 146, in execute
    return super().execute(query, vars)
           ~~~~~~~~~~~~~~~^^^^^^^^^^^^^
psycopg2.errors.UndefinedColumn: ERRORE:  la colonna "user_id" della relazione "audit_log" non esiste
LINE 2:         INSERT INTO audit_log (user_id, session_id, client_i...
                                       ^

2025-05-13 13:33:02,282 - CatastoAppLogger.AuditService - ERROR - FALLIMENTO REGISTRAZIONE AUDIT: User 4, Azione 'LOGOUT_SUCCESS'. Errore: ERRORE:  la colonna "user_id" della relazione "audit_log" non esiste
LINE 2:         INSERT INTO audit_log (user_id, session_id, client_i...
                                       ^
Traceback (most recent call last):
  File "C:\Users\saint\catasto\acs\core\services\audit_service.py", line 26, in record_audit
    db_manager.execute_query(query, (
    ~~~~~~~~~~~~~~~~~~~~~~~~^^^^^^^^^
        user_id, session_id, client_ip_address, action,
        ^^^^^^^^^^^^^^^^^^^^^^^^^^^^^^^^^^^^^^^^^^^^^^^
        table_name, record_id_str, details, success, datetime.now()
        ^^^^^^^^^^^^^^^^^^^^^^^^^^^^^^^^^^^^^^^^^^^^^^^^^^^^^^^^^^^
    ))
    ^^
  File "C:\Users\saint\catasto\acs\core\db_manager.py", line 181, in execute_query
    cur.execute(query, params)
    ~~~~~~~~~~~^^^^^^^^^^^^^^^
  File "C:\Users\saint\AppData\Local\Programs\Python\Python313\Lib\site-packages\psycopg2\extras.py", line 146, in execute
    return super().execute(query, vars)
           ~~~~~~~~~~~~~~~^^^^^^^^^^^^^
psycopg2.errors.UndefinedColumn: ERRORE:  la colonna "user_id" della relazione "audit_log" non esiste
LINE 2:         INSERT INTO audit_log (user_id, session_id, client_i...
                                       ^

2025-05-13 13:33:02,288 - CatastoAppLogger - INFO - Chiusura connessione al database...
2025-05-13 13:33:02,289 - CatastoDBLogger - INFO - Disconnessione dal database riuscita.
2025-05-13 13:33:02,289 - CatastoAppLogger - INFO - Applicazione Catasto Storico terminata.
2025-05-13 14:55:36,566 - CatastoAppLogger - INFO - Avvio Applicazione Catasto Storico...
2025-05-13 14:55:36,610 - CatastoAppLogger.ConfigLoader - INFO - Configurazione database caricata da 'config.ini'.
2025-05-13 14:55:36,616 - CatastoDBLogger - INFO - Tentativo di connessione al database: catasto_storico@localhost
2025-05-13 14:55:36,740 - CatastoDBLogger - INFO - Connessione al database 'catasto_storico' riuscita.
2025-05-13 14:55:36,746 - CatastoDBLogger - INFO - Search path impostato a: catasto, public
2025-05-13 14:55:36,758 - CatastoAppLogger - INFO - Indirizzo IP client rilevato/usato: 10.8.65.148
2025-05-13 14:56:01,303 - CatastoAppLogger.UtentiService - INFO - Tentativo di registrazione per l'utente: sa
2025-05-13 14:56:01,317 - CatastoDBLogger - ERROR - Errore Database durante l'esecuzione della query: SELECT id FROM utenti WHERE username = %s OR email = %s... Errore: ERRORE:  la relazione "utenti" non esiste
LINE 1: SELECT id FROM utenti WHERE username = 'sa' OR email = 'sa@s...
                       ^
Traceback (most recent call last):
  File "U:\catasto\acs\core\db_manager.py", line 181, in execute_query
    cur.execute(query, params)
    ~~~~~~~~~~~^^^^^^^^^^^^^^^
  File "C:\Users\ipabcrmm\AppData\Roaming\Python\Python313\site-packages\psycopg2\extras.py", line 146, in execute
    return super().execute(query, vars)
           ~~~~~~~~~~~~~~~^^^^^^^^^^^^^
psycopg2.errors.UndefinedTable: ERRORE:  la relazione "utenti" non esiste
LINE 1: SELECT id FROM utenti WHERE username = 'sa' OR email = 'sa@s...
                       ^

2025-05-13 14:56:01,420 - CatastoAppLogger.UtentiService - ERROR - Errore critico durante la registrazione dell'utente 'sa': ERRORE:  la relazione "utenti" non esiste
LINE 1: SELECT id FROM utenti WHERE username = 'sa' OR email = 'sa@s...
                       ^
Traceback (most recent call last):
  File "U:\catasto\acs\core\services\utenti_service.py", line 78, in register_user_service
    existing_user = db_manager.execute_query(check_query, (username, email), fetch_one=True)
  File "U:\catasto\acs\core\db_manager.py", line 181, in execute_query
    cur.execute(query, params)
    ~~~~~~~~~~~^^^^^^^^^^^^^^^
  File "C:\Users\ipabcrmm\AppData\Roaming\Python\Python313\site-packages\psycopg2\extras.py", line 146, in execute
    return super().execute(query, vars)
           ~~~~~~~~~~~~~~~^^^^^^^^^^^^^
psycopg2.errors.UndefinedTable: ERRORE:  la relazione "utenti" non esiste
LINE 1: SELECT id FROM utenti WHERE username = 'sa' OR email = 'sa@s...
                       ^

2025-05-13 14:56:01,494 - CatastoDBLogger - INFO - Rollback della transazione eseguito.
2025-05-13 14:56:01,505 - CatastoDBLogger - ERROR - Errore Database durante l'esecuzione della query: 
        INSERT INTO audit_log (user_id, session_id, client_ip_address, action_performed, 
                               table_name_affected, record_id_affected, details, success, timestamp)
        ... Errore: ERRORE:  la colonna "user_id" della relazione "audit_log" non esiste
LINE 2:         INSERT INTO audit_log (user_id, session_id, client_i...
                                       ^
Traceback (most recent call last):
  File "U:\catasto\acs\core\services\utenti_service.py", line 78, in register_user_service
    existing_user = db_manager.execute_query(check_query, (username, email), fetch_one=True)
  File "U:\catasto\acs\core\db_manager.py", line 181, in execute_query
    cur.execute(query, params)
    ~~~~~~~~~~~^^^^^^^^^^^^^^^
  File "C:\Users\ipabcrmm\AppData\Roaming\Python\Python313\site-packages\psycopg2\extras.py", line 146, in execute
    return super().execute(query, vars)
           ~~~~~~~~~~~~~~~^^^^^^^^^^^^^
psycopg2.errors.UndefinedTable: ERRORE:  la relazione "utenti" non esiste
LINE 1: SELECT id FROM utenti WHERE username = 'sa' OR email = 'sa@s...
                       ^


During handling of the above exception, another exception occurred:

Traceback (most recent call last):
  File "U:\catasto\acs\core\db_manager.py", line 181, in execute_query
    cur.execute(query, params)
    ~~~~~~~~~~~^^^^^^^^^^^^^^^
  File "C:\Users\ipabcrmm\AppData\Roaming\Python\Python313\site-packages\psycopg2\extras.py", line 146, in execute
    return super().execute(query, vars)
           ~~~~~~~~~~~~~~~^^^^^^^^^^^^^
psycopg2.errors.UndefinedColumn: ERRORE:  la colonna "user_id" della relazione "audit_log" non esiste
LINE 2:         INSERT INTO audit_log (user_id, session_id, client_i...
                                       ^

2025-05-13 14:56:01,553 - CatastoAppLogger.AuditService - ERROR - FALLIMENTO REGISTRAZIONE AUDIT: User None, Azione 'REGISTER_USER_FAIL'. Errore: ERRORE:  la colonna "user_id" della relazione "audit_log" non esiste
LINE 2:         INSERT INTO audit_log (user_id, session_id, client_i...
                                       ^
Traceback (most recent call last):
  File "U:\catasto\acs\core\services\utenti_service.py", line 78, in register_user_service
    existing_user = db_manager.execute_query(check_query, (username, email), fetch_one=True)
  File "U:\catasto\acs\core\db_manager.py", line 181, in execute_query
    cur.execute(query, params)
    ~~~~~~~~~~~^^^^^^^^^^^^^^^
  File "C:\Users\ipabcrmm\AppData\Roaming\Python\Python313\site-packages\psycopg2\extras.py", line 146, in execute
    return super().execute(query, vars)
           ~~~~~~~~~~~~~~~^^^^^^^^^^^^^
psycopg2.errors.UndefinedTable: ERRORE:  la relazione "utenti" non esiste
LINE 1: SELECT id FROM utenti WHERE username = 'sa' OR email = 'sa@s...
                       ^


During handling of the above exception, another exception occurred:

Traceback (most recent call last):
  File "U:\catasto\acs\core\services\audit_service.py", line 26, in record_audit
    db_manager.execute_query(query, (
    ~~~~~~~~~~~~~~~~~~~~~~~~^^^^^^^^^
        user_id, session_id, client_ip_address, action,
        ^^^^^^^^^^^^^^^^^^^^^^^^^^^^^^^^^^^^^^^^^^^^^^^
        table_name, record_id_str, details, success, datetime.now()
        ^^^^^^^^^^^^^^^^^^^^^^^^^^^^^^^^^^^^^^^^^^^^^^^^^^^^^^^^^^^
    ))
    ^^
  File "U:\catasto\acs\core\db_manager.py", line 181, in execute_query
    cur.execute(query, params)
    ~~~~~~~~~~~^^^^^^^^^^^^^^^
  File "C:\Users\ipabcrmm\AppData\Roaming\Python\Python313\site-packages\psycopg2\extras.py", line 146, in execute
    return super().execute(query, vars)
           ~~~~~~~~~~~~~~~^^^^^^^^^^^^^
psycopg2.errors.UndefinedColumn: ERRORE:  la colonna "user_id" della relazione "audit_log" non esiste
LINE 2:         INSERT INTO audit_log (user_id, session_id, client_i...
                                       ^

2025-05-13 14:56:01,637 - CatastoAppLogger - ERROR - Errore critico durante la registrazione: ERRORE:  la relazione "utenti" non esiste
LINE 1: SELECT id FROM utenti WHERE username = 'sa' OR email = 'sa@s...
                       ^
Traceback (most recent call last):
  File "U:\catasto\acs\main_app.py", line 141, in authenticate_user
    new_user_id = utenti_service.register_user_service(
        db_manager_instance, username_reg, password_reg1, email_reg,
    ...<4 lines>...
        # Considera di passare un dizionario audit_params se necessario
    )
  File "U:\catasto\acs\core\services\utenti_service.py", line 78, in register_user_service
    existing_user = db_manager.execute_query(check_query, (username, email), fetch_one=True)
  File "U:\catasto\acs\core\db_manager.py", line 181, in execute_query
    cur.execute(query, params)
    ~~~~~~~~~~~^^^^^^^^^^^^^^^
  File "C:\Users\ipabcrmm\AppData\Roaming\Python\Python313\site-packages\psycopg2\extras.py", line 146, in execute
    return super().execute(query, vars)
           ~~~~~~~~~~~~~~~^^^^^^^^^^^^^
psycopg2.errors.UndefinedTable: ERRORE:  la relazione "utenti" non esiste
LINE 1: SELECT id FROM utenti WHERE username = 'sa' OR email = 'sa@s...
                       ^

2025-05-13 14:56:10,544 - CatastoAppLogger.UtentiService - INFO - Tentativo di login per l'utente: sa
2025-05-13 14:56:10,550 - CatastoDBLogger - ERROR - Errore Database durante l'esecuzione della query: SELECT id, password_hash, role_id, is_active FROM utenti WHERE username = %s... Errore: ERRORE:  la relazione "utenti" non esiste
LINE 1: SELECT id, password_hash, role_id, is_active FROM utenti WHE...
                                                          ^
Traceback (most recent call last):
  File "U:\catasto\acs\core\db_manager.py", line 181, in execute_query
    cur.execute(query, params)
    ~~~~~~~~~~~^^^^^^^^^^^^^^^
  File "C:\Users\ipabcrmm\AppData\Roaming\Python\Python313\site-packages\psycopg2\extras.py", line 146, in execute
    return super().execute(query, vars)
           ~~~~~~~~~~~~~~~^^^^^^^^^^^^^
psycopg2.errors.UndefinedTable: ERRORE:  la relazione "utenti" non esiste
LINE 1: SELECT id, password_hash, role_id, is_active FROM utenti WHE...
                                                          ^

2025-05-13 14:56:10,569 - CatastoAppLogger.UtentiService - ERROR - Errore DB durante il recupero utente 'sa' per login: ERRORE:  la relazione "utenti" non esiste
LINE 1: SELECT id, password_hash, role_id, is_active FROM utenti WHE...
                                                          ^

2025-05-13 14:56:10,574 - CatastoDBLogger - ERROR - Errore Database durante l'esecuzione della query: 
        INSERT INTO audit_log (user_id, session_id, client_ip_address, action_performed, 
                               table_name_affected, record_id_affected, details, success, timestamp)
        ... Errore: ERRORE:  la colonna "user_id" della relazione "audit_log" non esiste
LINE 2:         INSERT INTO audit_log (user_id, session_id, client_i...
                                       ^
Traceback (most recent call last):
  File "U:\catasto\acs\core\services\utenti_service.py", line 152, in login_user_service
    user_data = db_manager.execute_query(query, (username,), fetch_one=True)
  File "U:\catasto\acs\core\db_manager.py", line 181, in execute_query
    cur.execute(query, params)
    ~~~~~~~~~~~^^^^^^^^^^^^^^^
  File "C:\Users\ipabcrmm\AppData\Roaming\Python\Python313\site-packages\psycopg2\extras.py", line 146, in execute
    return super().execute(query, vars)
           ~~~~~~~~~~~~~~~^^^^^^^^^^^^^
psycopg2.errors.UndefinedTable: ERRORE:  la relazione "utenti" non esiste
LINE 1: SELECT id, password_hash, role_id, is_active FROM utenti WHE...
                                                          ^


During handling of the above exception, another exception occurred:

Traceback (most recent call last):
  File "U:\catasto\acs\core\db_manager.py", line 181, in execute_query
    cur.execute(query, params)
    ~~~~~~~~~~~^^^^^^^^^^^^^^^
  File "C:\Users\ipabcrmm\AppData\Roaming\Python\Python313\site-packages\psycopg2\extras.py", line 146, in execute
    return super().execute(query, vars)
           ~~~~~~~~~~~~~~~^^^^^^^^^^^^^
psycopg2.errors.UndefinedColumn: ERRORE:  la colonna "user_id" della relazione "audit_log" non esiste
LINE 2:         INSERT INTO audit_log (user_id, session_id, client_i...
                                       ^

2025-05-13 14:56:10,621 - CatastoAppLogger.AuditService - ERROR - FALLIMENTO REGISTRAZIONE AUDIT: User None, Azione 'LOGIN_FAIL'. Errore: ERRORE:  la colonna "user_id" della relazione "audit_log" non esiste
LINE 2:         INSERT INTO audit_log (user_id, session_id, client_i...
                                       ^
Traceback (most recent call last):
  File "U:\catasto\acs\core\services\utenti_service.py", line 152, in login_user_service
    user_data = db_manager.execute_query(query, (username,), fetch_one=True)
  File "U:\catasto\acs\core\db_manager.py", line 181, in execute_query
    cur.execute(query, params)
    ~~~~~~~~~~~^^^^^^^^^^^^^^^
  File "C:\Users\ipabcrmm\AppData\Roaming\Python\Python313\site-packages\psycopg2\extras.py", line 146, in execute
    return super().execute(query, vars)
           ~~~~~~~~~~~~~~~^^^^^^^^^^^^^
psycopg2.errors.UndefinedTable: ERRORE:  la relazione "utenti" non esiste
LINE 1: SELECT id, password_hash, role_id, is_active FROM utenti WHE...
                                                          ^


During handling of the above exception, another exception occurred:

Traceback (most recent call last):
  File "U:\catasto\acs\core\services\audit_service.py", line 26, in record_audit
    db_manager.execute_query(query, (
    ~~~~~~~~~~~~~~~~~~~~~~~~^^^^^^^^^
        user_id, session_id, client_ip_address, action,
        ^^^^^^^^^^^^^^^^^^^^^^^^^^^^^^^^^^^^^^^^^^^^^^^
        table_name, record_id_str, details, success, datetime.now()
        ^^^^^^^^^^^^^^^^^^^^^^^^^^^^^^^^^^^^^^^^^^^^^^^^^^^^^^^^^^^
    ))
    ^^
  File "U:\catasto\acs\core\db_manager.py", line 181, in execute_query
    cur.execute(query, params)
    ~~~~~~~~~~~^^^^^^^^^^^^^^^
  File "C:\Users\ipabcrmm\AppData\Roaming\Python\Python313\site-packages\psycopg2\extras.py", line 146, in execute
    return super().execute(query, vars)
           ~~~~~~~~~~~~~~~^^^^^^^^^^^^^
psycopg2.errors.UndefinedColumn: ERRORE:  la colonna "user_id" della relazione "audit_log" non esiste
LINE 2:         INSERT INTO audit_log (user_id, session_id, client_i...
                                       ^

2025-05-13 14:56:22,587 - CatastoAppLogger - INFO - Autenticazione fallita o utente ha scelto di uscire. Chiusura applicazione.
2025-05-13 14:56:22,592 - CatastoDBLogger - INFO - Disconnessione dal database riuscita.
2025-05-13 14:59:29,691 - CatastoAppLogger - INFO - Avvio Applicazione Catasto Storico...
2025-05-13 14:59:29,725 - CatastoAppLogger.ConfigLoader - INFO - Configurazione database caricata da 'config.ini'.
2025-05-13 14:59:29,730 - CatastoDBLogger - INFO - Tentativo di connessione al database: catasto_storico@localhost
2025-05-13 14:59:29,847 - CatastoDBLogger - INFO - Connessione al database 'catasto_storico' riuscita.
2025-05-13 14:59:29,852 - CatastoDBLogger - INFO - Search path impostato a: catasto, public
2025-05-13 14:59:29,858 - CatastoAppLogger - INFO - Indirizzo IP client rilevato/usato: 10.8.65.148
2025-05-13 14:59:41,056 - CatastoAppLogger.UtentiService - INFO - Tentativo di registrazione per l'utente: sa
2025-05-13 14:59:41,326 - CatastoAppLogger.UtentiService - INFO - Utente 'sa' (ID: 1) registrato con successo.
2025-05-13 14:59:41,335 - CatastoDBLogger - ERROR - Errore Database durante l'esecuzione della query: 
        INSERT INTO audit_log (user_id, session_id, client_ip_address, action_performed, 
                               table_name_affected, record_id_affected, details, success, timestamp)
        ... Errore: ERRORE:  la colonna "user_id" della relazione "audit_log" non esiste
LINE 2:         INSERT INTO audit_log (user_id, session_id, client_i...
                                       ^
Traceback (most recent call last):
  File "U:\catasto\acs\core\db_manager.py", line 181, in execute_query
    cur.execute(query, params)
    ~~~~~~~~~~~^^^^^^^^^^^^^^^
  File "C:\Users\ipabcrmm\AppData\Roaming\Python\Python313\site-packages\psycopg2\extras.py", line 146, in execute
    return super().execute(query, vars)
           ~~~~~~~~~~~~~~~^^^^^^^^^^^^^
psycopg2.errors.UndefinedColumn: ERRORE:  la colonna "user_id" della relazione "audit_log" non esiste
LINE 2:         INSERT INTO audit_log (user_id, session_id, client_i...
                                       ^

2025-05-13 14:59:41,439 - CatastoAppLogger.AuditService - ERROR - FALLIMENTO REGISTRAZIONE AUDIT: User 1, Azione 'REGISTER_USER_SUCCESS'. Errore: ERRORE:  la colonna "user_id" della relazione "audit_log" non esiste
LINE 2:         INSERT INTO audit_log (user_id, session_id, client_i...
                                       ^
Traceback (most recent call last):
  File "U:\catasto\acs\core\services\audit_service.py", line 26, in record_audit
    db_manager.execute_query(query, (
    ~~~~~~~~~~~~~~~~~~~~~~~~^^^^^^^^^
        user_id, session_id, client_ip_address, action,
        ^^^^^^^^^^^^^^^^^^^^^^^^^^^^^^^^^^^^^^^^^^^^^^^
        table_name, record_id_str, details, success, datetime.now()
        ^^^^^^^^^^^^^^^^^^^^^^^^^^^^^^^^^^^^^^^^^^^^^^^^^^^^^^^^^^^
    ))
    ^^
  File "U:\catasto\acs\core\db_manager.py", line 181, in execute_query
    cur.execute(query, params)
    ~~~~~~~~~~~^^^^^^^^^^^^^^^
  File "C:\Users\ipabcrmm\AppData\Roaming\Python\Python313\site-packages\psycopg2\extras.py", line 146, in execute
    return super().execute(query, vars)
           ~~~~~~~~~~~~~~~^^^^^^^^^^^^^
psycopg2.errors.UndefinedColumn: ERRORE:  la colonna "user_id" della relazione "audit_log" non esiste
LINE 2:         INSERT INTO audit_log (user_id, session_id, client_i...
                                       ^

2025-05-13 15:03:53,784 - CatastoAppLogger - INFO - Autenticazione fallita o utente ha scelto di uscire. Chiusura applicazione.
2025-05-13 15:03:53,790 - CatastoDBLogger - INFO - Disconnessione dal database riuscita.
2025-05-13 15:04:36,167 - CatastoAppLogger - INFO - Avvio Applicazione Catasto Storico...
2025-05-13 15:04:36,200 - CatastoAppLogger.ConfigLoader - INFO - Configurazione database caricata da 'config.ini'.
2025-05-13 15:04:36,205 - CatastoDBLogger - INFO - Tentativo di connessione al database: catasto_storico@localhost
2025-05-13 15:04:36,320 - CatastoDBLogger - INFO - Connessione al database 'catasto_storico' riuscita.
2025-05-13 15:04:36,325 - CatastoDBLogger - INFO - Search path impostato a: catasto, public
2025-05-13 15:04:36,336 - CatastoAppLogger - INFO - Indirizzo IP client rilevato/usato: 10.8.65.148
2025-05-13 15:04:45,920 - CatastoAppLogger.UtentiService - INFO - Tentativo di registrazione per l'utente: sa
2025-05-13 15:04:45,926 - CatastoAppLogger.UtentiService - WARNING - Username 'sa' o email 'sa' già esistente.
2025-05-13 15:04:45,931 - CatastoDBLogger - INFO - Rollback della transazione eseguito.
2025-05-13 15:04:45,938 - CatastoDBLogger - ERROR - Errore Database durante l'esecuzione della query: 
        INSERT INTO audit_log (user_id, session_id, client_ip_address, action_performed, 
                               table_name_affected, record_id_affected, details, success, timestamp)
        ... Errore: ERRORE:  la colonna "user_id" della relazione "audit_log" non esiste
LINE 2:         INSERT INTO audit_log (user_id, session_id, client_i...
                                       ^
Traceback (most recent call last):
  File "U:\catasto\acs\core\db_manager.py", line 181, in execute_query
    cur.execute(query, params)
    ~~~~~~~~~~~^^^^^^^^^^^^^^^
  File "C:\Users\ipabcrmm\AppData\Roaming\Python\Python313\site-packages\psycopg2\extras.py", line 146, in execute
    return super().execute(query, vars)
           ~~~~~~~~~~~~~~~^^^^^^^^^^^^^
psycopg2.errors.UndefinedColumn: ERRORE:  la colonna "user_id" della relazione "audit_log" non esiste
LINE 2:         INSERT INTO audit_log (user_id, session_id, client_i...
                                       ^

2025-05-13 15:04:46,039 - CatastoAppLogger.AuditService - ERROR - FALLIMENTO REGISTRAZIONE AUDIT: User None, Azione 'REGISTER_USER_FAIL'. Errore: ERRORE:  la colonna "user_id" della relazione "audit_log" non esiste
LINE 2:         INSERT INTO audit_log (user_id, session_id, client_i...
                                       ^
Traceback (most recent call last):
  File "U:\catasto\acs\core\services\audit_service.py", line 26, in record_audit
    db_manager.execute_query(query, (
    ~~~~~~~~~~~~~~~~~~~~~~~~^^^^^^^^^
        user_id, session_id, client_ip_address, action,
        ^^^^^^^^^^^^^^^^^^^^^^^^^^^^^^^^^^^^^^^^^^^^^^^
        table_name, record_id_str, details, success, datetime.now()
        ^^^^^^^^^^^^^^^^^^^^^^^^^^^^^^^^^^^^^^^^^^^^^^^^^^^^^^^^^^^
    ))
    ^^
  File "U:\catasto\acs\core\db_manager.py", line 181, in execute_query
    cur.execute(query, params)
    ~~~~~~~~~~~^^^^^^^^^^^^^^^
  File "C:\Users\ipabcrmm\AppData\Roaming\Python\Python313\site-packages\psycopg2\extras.py", line 146, in execute
    return super().execute(query, vars)
           ~~~~~~~~~~~~~~~^^^^^^^^^^^^^
psycopg2.errors.UndefinedColumn: ERRORE:  la colonna "user_id" della relazione "audit_log" non esiste
LINE 2:         INSERT INTO audit_log (user_id, session_id, client_i...
                                       ^

2025-05-13 15:09:43,685 - CatastoAppLogger - INFO - Autenticazione fallita o utente ha scelto di uscire. Chiusura applicazione.
2025-05-13 15:09:43,690 - CatastoDBLogger - INFO - Disconnessione dal database riuscita.
2025-05-13 15:26:14,794 - CatastoAppLogger - INFO - Avvio Applicazione Catasto Storico...
2025-05-13 15:26:14,830 - CatastoAppLogger.ConfigLoader - INFO - Configurazione database caricata da 'config.ini'.
2025-05-13 15:26:14,834 - CatastoDBLogger - INFO - Tentativo di connessione al database: catasto_storico@localhost
2025-05-13 15:26:15,068 - CatastoDBLogger - INFO - Connessione al database 'catasto_storico' riuscita.
2025-05-13 15:26:15,073 - CatastoDBLogger - INFO - Search path impostato a: catasto, public
2025-05-13 15:26:15,081 - CatastoAppLogger - INFO - Indirizzo IP client rilevato/usato: 10.8.65.148
2025-05-13 15:26:26,696 - CatastoAppLogger.UtentiService - INFO - Tentativo di registrazione per l'utente: sa
2025-05-13 15:26:26,704 - CatastoAppLogger.UtentiService - WARNING - Username 'sa' o email 'sa' già esistente.
2025-05-13 15:26:26,708 - CatastoDBLogger - INFO - Rollback della transazione eseguito.
2025-05-13 15:26:26,715 - CatastoDBLogger - ERROR - Errore Database durante l'esecuzione della query: 
        INSERT INTO audit_log (user_id, session_id, client_ip_address, action_performed, 
                               table_name_affected, record_id_affected, details, success, timestamp)
        ... Errore: ERRORE:  la colonna "user_id" della relazione "audit_log" non esiste
LINE 2:         INSERT INTO audit_log (user_id, session_id, client_i...
                                       ^
Traceback (most recent call last):
  File "U:\catasto\acs\core\db_manager.py", line 181, in execute_query
    cur.execute(query, params)
    ~~~~~~~~~~~^^^^^^^^^^^^^^^
  File "C:\Users\ipabcrmm\AppData\Roaming\Python\Python313\site-packages\psycopg2\extras.py", line 146, in execute
    return super().execute(query, vars)
           ~~~~~~~~~~~~~~~^^^^^^^^^^^^^
psycopg2.errors.UndefinedColumn: ERRORE:  la colonna "user_id" della relazione "audit_log" non esiste
LINE 2:         INSERT INTO audit_log (user_id, session_id, client_i...
                                       ^

2025-05-13 15:26:26,823 - CatastoAppLogger.AuditService - ERROR - FALLIMENTO REGISTRAZIONE AUDIT: User None, Azione 'REGISTER_USER_FAIL'. Errore: ERRORE:  la colonna "user_id" della relazione "audit_log" non esiste
LINE 2:         INSERT INTO audit_log (user_id, session_id, client_i...
                                       ^
Traceback (most recent call last):
  File "U:\catasto\acs\core\services\audit_service.py", line 26, in record_audit
    db_manager.execute_query(query, (
    ~~~~~~~~~~~~~~~~~~~~~~~~^^^^^^^^^
        user_id, session_id, client_ip_address, action,
        ^^^^^^^^^^^^^^^^^^^^^^^^^^^^^^^^^^^^^^^^^^^^^^^
        table_name, record_id_str, details, success, datetime.now()
        ^^^^^^^^^^^^^^^^^^^^^^^^^^^^^^^^^^^^^^^^^^^^^^^^^^^^^^^^^^^
    ))
    ^^
  File "U:\catasto\acs\core\db_manager.py", line 181, in execute_query
    cur.execute(query, params)
    ~~~~~~~~~~~^^^^^^^^^^^^^^^
  File "C:\Users\ipabcrmm\AppData\Roaming\Python\Python313\site-packages\psycopg2\extras.py", line 146, in execute
    return super().execute(query, vars)
           ~~~~~~~~~~~~~~~^^^^^^^^^^^^^
psycopg2.errors.UndefinedColumn: ERRORE:  la colonna "user_id" della relazione "audit_log" non esiste
LINE 2:         INSERT INTO audit_log (user_id, session_id, client_i...
                                       ^

2025-05-13 15:26:37,456 - CatastoAppLogger.UtentiService - INFO - Tentativo di login per l'utente: sa
2025-05-13 15:26:37,723 - CatastoAppLogger.UtentiService - INFO - Utente 'sa' (ID: 1) loggato con successo. Sessione: 1b07169b-9bd3-475b-907e-a085e0f746b5
2025-05-13 15:26:37,729 - CatastoDBLogger - ERROR - Errore Database durante l'esecuzione della query: 
        INSERT INTO audit_log (user_id, session_id, client_ip_address, action_performed, 
                               table_name_affected, record_id_affected, details, success, timestamp)
        ... Errore: ERRORE:  la colonna "user_id" della relazione "audit_log" non esiste
LINE 2:         INSERT INTO audit_log (user_id, session_id, client_i...
                                       ^
Traceback (most recent call last):
  File "U:\catasto\acs\core\db_manager.py", line 181, in execute_query
    cur.execute(query, params)
    ~~~~~~~~~~~^^^^^^^^^^^^^^^
  File "C:\Users\ipabcrmm\AppData\Roaming\Python\Python313\site-packages\psycopg2\extras.py", line 146, in execute
    return super().execute(query, vars)
           ~~~~~~~~~~~~~~~^^^^^^^^^^^^^
psycopg2.errors.UndefinedColumn: ERRORE:  la colonna "user_id" della relazione "audit_log" non esiste
LINE 2:         INSERT INTO audit_log (user_id, session_id, client_i...
                                       ^

2025-05-13 15:26:37,757 - CatastoAppLogger.AuditService - ERROR - FALLIMENTO REGISTRAZIONE AUDIT: User 1, Azione 'LOGIN_SUCCESS'. Errore: ERRORE:  la colonna "user_id" della relazione "audit_log" non esiste
LINE 2:         INSERT INTO audit_log (user_id, session_id, client_i...
                                       ^
Traceback (most recent call last):
  File "U:\catasto\acs\core\services\audit_service.py", line 26, in record_audit
    db_manager.execute_query(query, (
    ~~~~~~~~~~~~~~~~~~~~~~~~^^^^^^^^^
        user_id, session_id, client_ip_address, action,
        ^^^^^^^^^^^^^^^^^^^^^^^^^^^^^^^^^^^^^^^^^^^^^^^
        table_name, record_id_str, details, success, datetime.now()
        ^^^^^^^^^^^^^^^^^^^^^^^^^^^^^^^^^^^^^^^^^^^^^^^^^^^^^^^^^^^
    ))
    ^^
  File "U:\catasto\acs\core\db_manager.py", line 181, in execute_query
    cur.execute(query, params)
    ~~~~~~~~~~~^^^^^^^^^^^^^^^
  File "C:\Users\ipabcrmm\AppData\Roaming\Python\Python313\site-packages\psycopg2\extras.py", line 146, in execute
    return super().execute(query, vars)
           ~~~~~~~~~~~~~~~^^^^^^^^^^^^^
psycopg2.errors.UndefinedColumn: ERRORE:  la colonna "user_id" della relazione "audit_log" non esiste
LINE 2:         INSERT INTO audit_log (user_id, session_id, client_i...
                                       ^

2025-05-13 15:26:37,796 - CatastoAppLogger - INFO - Login successo per utente ID 1, Ruolo ID 2, Sessione 1b07169b-9bd3-475b-907e-a085e0f746b5
2025-05-13 15:26:37,801 - CatastoAppLogger.MenuHandler - INFO - Utente ID 1 (Ruolo ID: 2, Sessione: 1b07169b-9bd3-475b-907e-a085e0f746b5) ha effettuato l'accesso al menu principale.
2025-05-13 15:26:37,809 - CatastoAppLogger - ERROR - Errore non gestito nel ciclo principale dell'applicazione: name 'ADMIN_ROLE_ID' is not defined
Traceback (most recent call last):
  File "U:\catasto\acs\main_app.py", line 209, in main
    menu_principale(db, logged_in_user_id, current_user_role_id, current_session_id, client_ip_address)
    ~~~~~~~~~~~~~~~^^^^^^^^^^^^^^^^^^^^^^^^^^^^^^^^^^^^^^^^^^^^^^^^^^^^^^^^^^^^^^^^^^^^^^^^^^^^^^^^^^^^
  File "U:\catasto\acs\ui\console\menu_handler.py", line 936, in menu_principale
    if current_user_role_id == ADMIN_ROLE_ID:
                               ^^^^^^^^^^^^^
NameError: name 'ADMIN_ROLE_ID' is not defined
2025-05-13 15:26:37,938 - CatastoAppLogger - INFO - Esecuzione logout per utente ID 1, sessione 1b07169b-9bd3-475b-907e-a085e0f746b5...
2025-05-13 15:26:37,943 - CatastoAppLogger.UtentiService - INFO - Tentativo di logout per utente ID: 1, Sessione: 1b07169b-9bd3-475b-907e-a085e0f746b5
2025-05-13 15:26:37,949 - CatastoAppLogger.UtentiService - INFO - Logout utente ID 1, Sessione 1b07169b-9bd3-475b-907e-a085e0f746b5 registrato con successo.
2025-05-13 15:26:37,955 - CatastoDBLogger - ERROR - Errore Database durante l'esecuzione della query: 
        INSERT INTO audit_log (user_id, session_id, client_ip_address, action_performed, 
                               table_name_affected, record_id_affected, details, success, timestamp)
        ... Errore: ERRORE:  la colonna "user_id" della relazione "audit_log" non esiste
LINE 2:         INSERT INTO audit_log (user_id, session_id, client_i...
                                       ^
Traceback (most recent call last):
  File "U:\catasto\acs\core\db_manager.py", line 181, in execute_query
    cur.execute(query, params)
    ~~~~~~~~~~~^^^^^^^^^^^^^^^
  File "C:\Users\ipabcrmm\AppData\Roaming\Python\Python313\site-packages\psycopg2\extras.py", line 146, in execute
    return super().execute(query, vars)
           ~~~~~~~~~~~~~~~^^^^^^^^^^^^^
psycopg2.errors.UndefinedColumn: ERRORE:  la colonna "user_id" della relazione "audit_log" non esiste
LINE 2:         INSERT INTO audit_log (user_id, session_id, client_i...
                                       ^

2025-05-13 15:26:37,977 - CatastoAppLogger.AuditService - ERROR - FALLIMENTO REGISTRAZIONE AUDIT: User 1, Azione 'LOGOUT_SUCCESS'. Errore: ERRORE:  la colonna "user_id" della relazione "audit_log" non esiste
LINE 2:         INSERT INTO audit_log (user_id, session_id, client_i...
                                       ^
Traceback (most recent call last):
  File "U:\catasto\acs\core\services\audit_service.py", line 26, in record_audit
    db_manager.execute_query(query, (
    ~~~~~~~~~~~~~~~~~~~~~~~~^^^^^^^^^
        user_id, session_id, client_ip_address, action,
        ^^^^^^^^^^^^^^^^^^^^^^^^^^^^^^^^^^^^^^^^^^^^^^^
        table_name, record_id_str, details, success, datetime.now()
        ^^^^^^^^^^^^^^^^^^^^^^^^^^^^^^^^^^^^^^^^^^^^^^^^^^^^^^^^^^^
    ))
    ^^
  File "U:\catasto\acs\core\db_manager.py", line 181, in execute_query
    cur.execute(query, params)
    ~~~~~~~~~~~^^^^^^^^^^^^^^^
  File "C:\Users\ipabcrmm\AppData\Roaming\Python\Python313\site-packages\psycopg2\extras.py", line 146, in execute
    return super().execute(query, vars)
           ~~~~~~~~~~~~~~~^^^^^^^^^^^^^
psycopg2.errors.UndefinedColumn: ERRORE:  la colonna "user_id" della relazione "audit_log" non esiste
LINE 2:         INSERT INTO audit_log (user_id, session_id, client_i...
                                       ^

2025-05-13 15:26:38,014 - CatastoAppLogger - INFO - Chiusura connessione al database...
2025-05-13 15:26:38,019 - CatastoDBLogger - INFO - Disconnessione dal database riuscita.
2025-05-13 15:26:38,025 - CatastoAppLogger - INFO - Applicazione Catasto Storico terminata.
2025-05-13 15:27:02,200 - CatastoAppLogger - INFO - Avvio Applicazione Catasto Storico...
2025-05-13 15:27:02,234 - CatastoAppLogger.ConfigLoader - INFO - Configurazione database caricata da 'config.ini'.
2025-05-13 15:27:02,239 - CatastoDBLogger - INFO - Tentativo di connessione al database: catasto_storico@localhost
2025-05-13 15:27:02,357 - CatastoDBLogger - INFO - Connessione al database 'catasto_storico' riuscita.
2025-05-13 15:27:02,362 - CatastoDBLogger - INFO - Search path impostato a: catasto, public
2025-05-13 15:27:02,367 - CatastoAppLogger - INFO - Indirizzo IP client rilevato/usato: 10.8.65.148
2025-05-13 15:27:05,699 - CatastoAppLogger.UtentiService - INFO - Tentativo di login per l'utente: sa
2025-05-13 15:27:05,965 - CatastoAppLogger.UtentiService - INFO - Utente 'sa' (ID: 1) loggato con successo. Sessione: 06404194-c017-47cc-bfce-c97b16e2e4d6
2025-05-13 15:27:05,972 - CatastoDBLogger - ERROR - Errore Database durante l'esecuzione della query: 
        INSERT INTO audit_log (user_id, session_id, client_ip_address, action_performed, 
                               table_name_affected, record_id_affected, details, success, timestamp)
        ... Errore: ERRORE:  la colonna "user_id" della relazione "audit_log" non esiste
LINE 2:         INSERT INTO audit_log (user_id, session_id, client_i...
                                       ^
Traceback (most recent call last):
  File "U:\catasto\acs\core\db_manager.py", line 181, in execute_query
    cur.execute(query, params)
    ~~~~~~~~~~~^^^^^^^^^^^^^^^
  File "C:\Users\ipabcrmm\AppData\Roaming\Python\Python313\site-packages\psycopg2\extras.py", line 146, in execute
    return super().execute(query, vars)
           ~~~~~~~~~~~~~~~^^^^^^^^^^^^^
psycopg2.errors.UndefinedColumn: ERRORE:  la colonna "user_id" della relazione "audit_log" non esiste
LINE 2:         INSERT INTO audit_log (user_id, session_id, client_i...
                                       ^

2025-05-13 15:27:06,065 - CatastoAppLogger.AuditService - ERROR - FALLIMENTO REGISTRAZIONE AUDIT: User 1, Azione 'LOGIN_SUCCESS'. Errore: ERRORE:  la colonna "user_id" della relazione "audit_log" non esiste
LINE 2:         INSERT INTO audit_log (user_id, session_id, client_i...
                                       ^
Traceback (most recent call last):
  File "U:\catasto\acs\core\services\audit_service.py", line 26, in record_audit
    db_manager.execute_query(query, (
    ~~~~~~~~~~~~~~~~~~~~~~~~^^^^^^^^^
        user_id, session_id, client_ip_address, action,
        ^^^^^^^^^^^^^^^^^^^^^^^^^^^^^^^^^^^^^^^^^^^^^^^
        table_name, record_id_str, details, success, datetime.now()
        ^^^^^^^^^^^^^^^^^^^^^^^^^^^^^^^^^^^^^^^^^^^^^^^^^^^^^^^^^^^
    ))
    ^^
  File "U:\catasto\acs\core\db_manager.py", line 181, in execute_query
    cur.execute(query, params)
    ~~~~~~~~~~~^^^^^^^^^^^^^^^
  File "C:\Users\ipabcrmm\AppData\Roaming\Python\Python313\site-packages\psycopg2\extras.py", line 146, in execute
    return super().execute(query, vars)
           ~~~~~~~~~~~~~~~^^^^^^^^^^^^^
psycopg2.errors.UndefinedColumn: ERRORE:  la colonna "user_id" della relazione "audit_log" non esiste
LINE 2:         INSERT INTO audit_log (user_id, session_id, client_i...
                                       ^

2025-05-13 15:27:06,121 - CatastoAppLogger - INFO - Login successo per utente ID 1, Ruolo ID 2, Sessione 06404194-c017-47cc-bfce-c97b16e2e4d6
2025-05-13 15:27:06,126 - CatastoAppLogger.MenuHandler - INFO - Utente ID 1 (Ruolo ID: 2, Sessione: 06404194-c017-47cc-bfce-c97b16e2e4d6) ha effettuato l'accesso al menu principale.
2025-05-13 15:27:06,135 - CatastoAppLogger - ERROR - Errore non gestito nel ciclo principale dell'applicazione: name 'ADMIN_ROLE_ID' is not defined
Traceback (most recent call last):
  File "U:\catasto\acs\main_app.py", line 209, in main
    menu_principale(db, logged_in_user_id, current_user_role_id, current_session_id, client_ip_address)
    ~~~~~~~~~~~~~~~^^^^^^^^^^^^^^^^^^^^^^^^^^^^^^^^^^^^^^^^^^^^^^^^^^^^^^^^^^^^^^^^^^^^^^^^^^^^^^^^^^^^
  File "U:\catasto\acs\ui\console\menu_handler.py", line 936, in menu_principale
    if current_user_role_id == ADMIN_ROLE_ID:
                               ^^^^^^^^^^^^^
NameError: name 'ADMIN_ROLE_ID' is not defined
2025-05-13 15:27:06,235 - CatastoAppLogger - INFO - Esecuzione logout per utente ID 1, sessione 06404194-c017-47cc-bfce-c97b16e2e4d6...
2025-05-13 15:27:06,240 - CatastoAppLogger.UtentiService - INFO - Tentativo di logout per utente ID: 1, Sessione: 06404194-c017-47cc-bfce-c97b16e2e4d6
2025-05-13 15:27:06,245 - CatastoAppLogger.UtentiService - INFO - Logout utente ID 1, Sessione 06404194-c017-47cc-bfce-c97b16e2e4d6 registrato con successo.
2025-05-13 15:27:06,251 - CatastoDBLogger - ERROR - Errore Database durante l'esecuzione della query: 
        INSERT INTO audit_log (user_id, session_id, client_ip_address, action_performed, 
                               table_name_affected, record_id_affected, details, success, timestamp)
        ... Errore: ERRORE:  la colonna "user_id" della relazione "audit_log" non esiste
LINE 2:         INSERT INTO audit_log (user_id, session_id, client_i...
                                       ^
Traceback (most recent call last):
  File "U:\catasto\acs\core\db_manager.py", line 181, in execute_query
    cur.execute(query, params)
    ~~~~~~~~~~~^^^^^^^^^^^^^^^
  File "C:\Users\ipabcrmm\AppData\Roaming\Python\Python313\site-packages\psycopg2\extras.py", line 146, in execute
    return super().execute(query, vars)
           ~~~~~~~~~~~~~~~^^^^^^^^^^^^^
psycopg2.errors.UndefinedColumn: ERRORE:  la colonna "user_id" della relazione "audit_log" non esiste
LINE 2:         INSERT INTO audit_log (user_id, session_id, client_i...
                                       ^

2025-05-13 15:27:06,270 - CatastoAppLogger.AuditService - ERROR - FALLIMENTO REGISTRAZIONE AUDIT: User 1, Azione 'LOGOUT_SUCCESS'. Errore: ERRORE:  la colonna "user_id" della relazione "audit_log" non esiste
LINE 2:         INSERT INTO audit_log (user_id, session_id, client_i...
                                       ^
Traceback (most recent call last):
  File "U:\catasto\acs\core\services\audit_service.py", line 26, in record_audit
    db_manager.execute_query(query, (
    ~~~~~~~~~~~~~~~~~~~~~~~~^^^^^^^^^
        user_id, session_id, client_ip_address, action,
        ^^^^^^^^^^^^^^^^^^^^^^^^^^^^^^^^^^^^^^^^^^^^^^^
        table_name, record_id_str, details, success, datetime.now()
        ^^^^^^^^^^^^^^^^^^^^^^^^^^^^^^^^^^^^^^^^^^^^^^^^^^^^^^^^^^^
    ))
    ^^
  File "U:\catasto\acs\core\db_manager.py", line 181, in execute_query
    cur.execute(query, params)
    ~~~~~~~~~~~^^^^^^^^^^^^^^^
  File "C:\Users\ipabcrmm\AppData\Roaming\Python\Python313\site-packages\psycopg2\extras.py", line 146, in execute
    return super().execute(query, vars)
           ~~~~~~~~~~~~~~~^^^^^^^^^^^^^
psycopg2.errors.UndefinedColumn: ERRORE:  la colonna "user_id" della relazione "audit_log" non esiste
LINE 2:         INSERT INTO audit_log (user_id, session_id, client_i...
                                       ^

2025-05-13 15:27:06,303 - CatastoAppLogger - INFO - Chiusura connessione al database...
2025-05-13 15:27:06,308 - CatastoDBLogger - INFO - Disconnessione dal database riuscita.
2025-05-13 15:27:06,313 - CatastoAppLogger - INFO - Applicazione Catasto Storico terminata.
